ERROR:root:qwe
ERROR:root:qwe
ERROR:root:qwe
ERROR:root:b''
ERROR:root:CloudpaymentsStatusView <class 'ZeroDivisionError'> views.py 146 
 division by zero
ERROR:root:CloudpaymentsStatusView <class 'rest_framework.exceptions.ParseError'> views.py 137 
 JSON parse error - Expecting value: line 1 column 1 (char 0)
WARNING:django.request:Method Not Allowed: /cloudpayments_status/
WARNING:django.request:Not Found: /admin//config.php
ERROR:root:b'TransactionId=176131354&Amount=2.00&Currency=RUB&PaymentAmount=2.00&PaymentCurrency=RUB&OperationType=Payment&InvoiceId=&AccountId=user%40qweasd.com&SubscriptionId=sc_a2c77fefc854bc559a0277295716f&Name=MOMENTUM+R&Email=orlan_mh94%40mail.ru&DateTime=2019-07-23+15%3a38%3a58&IpAddress=192.168.3.35&IpCountry=&IpCity=&IpRegion=&IpDistrict=&IpLatitude=&IpLongitude=&CardFirstSix=533669&CardLastFour=7481&CardType=MasterCard&CardExpDate=08%2f21&Issuer=SBERBANK+OF+RUSSIA&IssuerBankCountry=RU&Description=%d0%9f%d0%be%d0%b4%d0%bf%d0%b8%d1%81%d0%ba%d0%b0+%d0%bd%d0%b0+%d0%b5%d0%b6%d0%b5%d0%bc%d0%b5%d1%81%d1%8f%d1%87%d0%bd%d1%8b%d0%b9+%d0%b4%d0%be%d1%81%d1%82%d1%83%d0%bf+%d0%ba+%d0%b1%d0%be%d1%82%d1%83+id%3d114+(%d0%9d%d0%b0%d0%b7%d0%b2%d0%b0%d0%bd%d0%b8%d0%b5+%d0%b1%d0%be%d1%82%d0%b0)+inbot24.ru&AuthCode=239382&Token=537937953&TestMode=0&Status=Completed&GatewayName=Tinkoff&TotalFee=0.08&CardProduct=MCS'
ERROR:root:b'TransactionId=176208761&Amount=2.00&Currency=RUB&PaymentAmount=2.00&PaymentCurrency=RUB&OperationType=Payment&InvoiceId=&AccountId=user%40qweasd.com&SubscriptionId=sc_642872f8508c326d70fd9896d77d1&Name=MOMENTUM+R&Email=orlan_mh94%40mail.ru&DateTime=2019-07-23+19%3a02%3a01&IpAddress=192.168.3.27&IpCountry=&IpCity=&IpRegion=&IpDistrict=&IpLatitude=&IpLongitude=&CardFirstSix=533669&CardLastFour=7481&CardType=MasterCard&CardExpDate=08%2f21&Issuer=SBERBANK+OF+RUSSIA&IssuerBankCountry=RU&Description=%d0%9f%d0%be%d0%b4%d0%bf%d0%b8%d1%81%d0%ba%d0%b0+%d0%bd%d0%b0+%d0%b5%d0%b6%d0%b5%d0%bc%d0%b5%d1%81%d1%8f%d1%87%d0%bd%d1%8b%d0%b9+%d0%b4%d0%be%d1%81%d1%82%d1%83%d0%bf+%d0%ba+%d0%b1%d0%be%d1%82%d1%83+id%3d114+(%d0%9d%d0%b0%d0%b7%d0%b2%d0%b0%d0%bd%d0%b8%d0%b5+%d0%b1%d0%be%d1%82%d0%b0)+inbot24.ru&AuthCode=291186&Token=538008841&TestMode=0&Status=Completed&GatewayName=Tinkoff&TotalFee=0.08&CardProduct=MCS'
WARNING:django.request:Not Found: /admin/config.php
WARNING:django.request:Not Found: /admin/config.php
ERROR:root:CloudpaymentsStatusView <class 'cabinet.models.Subscription.DoesNotExist'> views.py 467 
 Subscription matching query does not exist.
ERROR:root:CloudpaymentsStatusView <class 'cabinet.models.Subscription.DoesNotExist'> views.py 467 
 Subscription matching query does not exist.
WARNING:django.request:Unauthorized: /api/botusers/112/
WARNING:django.request:Unauthorized: /api/botusers/112/
WARNING:django.request:Forbidden: /api/botusers/112/
ERROR:root:BotUserView <class 'rest_framework.exceptions.NotFound'> views.py 278 
 Неправильная страница
WARNING:django.request:Not Found: /admin/config.php
WARNING:django.request:Forbidden: /api/botusers/113/
WARNING:django.request:Forbidden: /api/botusers/113/
WARNING:django.request:Forbidden: /api/botusers/113/
WARNING:django.request:Forbidden: /api/botusers/113/
WARNING:django.request:Forbidden: /api/botusers/113/
WARNING:django.request:Forbidden: /api/botusers/113/
WARNING:django.request:Forbidden: /api/analytics_data/113/
WARNING:django.request:Unauthorized: /api/bot_data/112/
WARNING:django.request:Unauthorized: /api/compaign_list/112/
WARNING:django.request:Unauthorized: /api/compaign_list/112/
WARNING:django.request:Unauthorized: /api/bot_data/112/
WARNING:django.request:Method Not Allowed (POST): /api/bot_data/112/compaign
WARNING:django.request:Method Not Allowed: /api/bot_data/112/compaign
WARNING:django.request:Bad Request: /api/compaign_list/112/
WARNING:django.request:Bad Request: /api/compaign_list/112/
WARNING:django.request:Bad Request: /api/compaign_list/112/
WARNING:django.request:Bad Request: /api/compaign_list/112/
WARNING:django.request:Bad Request: /api/compaign_list/112/
WARNING:django.request:Bad Request: /api/compaign_list/112/
WARNING:django.request:Unauthorized: /api/token/
WARNING:django.request:Unauthorized: /api/token/
WARNING:django.request:Unauthorized: /api/token/
WARNING:django.request:Bad Request: /api/compaign_list/112/
WARNING:django.request:Unauthorized: /api/token/
WARNING:django.request:Bad Request: /api/compaign_list/112/
WARNING:django.request:Bad Request: /api/compaign_list/112/
WARNING:django.request:Bad Request: /api/compaign_list/112/
WARNING:django.request:Bad Request: /api/compaign_list/112/
WARNING:django.request:Unauthorized: /api/bot_data/112/
WARNING:django.request:Unauthorized: /api/bot_data/112/
WARNING:django.request:Unauthorized: /api/bot_data/112/
WARNING:django.request:Unauthorized: /api/token/
WARNING:django.request:Unauthorized: /api/bot_data/112/
WARNING:django.request:Unauthorized: /api/bot_data/112/
WARNING:django.request:Unauthorized: /api/bot_data/112/
WARNING:django.request:Unauthorized: /api/bot_data/112/
WARNING:django.request:Method Not Allowed: /api/token/
WARNING:django.request:Method Not Allowed: /api/token/
WARNING:django.request:Unauthorized: /api/compaign_list/114/
WARNING:django.request:Method Not Allowed: /api/token/
WARNING:django.request:Method Not Allowed: /api/token/
WARNING:django.request:Method Not Allowed: /api/token/
WARNING:django.request:Method Not Allowed: /api/token/
WARNING:django.request:Method Not Allowed: /api/token/
WARNING:django.request:Method Not Allowed: /api/token/
WARNING:django.request:Method Not Allowed: /api/token/
WARNING:django.request:Method Not Allowed: /api/token/
WARNING:django.request:Method Not Allowed: /api/token/
WARNING:django.request:Method Not Allowed: /api/token/
WARNING:django.request:Method Not Allowed: /api/token/
WARNING:django.request:Method Not Allowed: /api/token/
ERROR:root:BotUserView <class 'rest_framework.exceptions.NotFound'> views.py 278 
 Неправильная страница
WARNING:django.request:Not Found: /api/compaign_list/112/
WARNING:django.request:Forbidden: /api/analytics_data/114/
WARNING:django.request:Forbidden: /api/analytics_data/114/
WARNING:django.request:Forbidden: /api/analytics_data/113/
WARNING:django.request:Forbidden: /api/compaign_list/114/
WARNING:django.request:Forbidden: /api/botusers/114/
WARNING:django.request:Forbidden: /api/analytics_data/114/
WARNING:django.request:Forbidden: /api/analytics_data/114/
WARNING:django.request:Forbidden: /api/botusers/114/
WARNING:django.request:Forbidden: /api/compaign_list/114/
WARNING:django.request:Forbidden: /api/analytics_data/114/
WARNING:django.request:Unauthorized: /api/token/
WARNING:django.request:Unauthorized: /api/token/
WARNING:django.request:Forbidden: /api/analytics_data/113/
WARNING:django.request:Forbidden: /api/botusers/113/
WARNING:django.request:Forbidden: /api/compaign_list/113/
WARNING:django.request:Forbidden: /api/botusers/113/
WARNING:django.request:Forbidden: /api/analytics_data/113/
WARNING:django.request:Forbidden: /api/botusers/113/
WARNING:django.request:Forbidden: /api/compaign_list/113/
WARNING:django.request:Forbidden: /api/botusers/113/
WARNING:django.request:Forbidden: /api/compaign_list/113/
WARNING:django.request:Forbidden: /api/analytics_data/113/
WARNING:django.request:Forbidden: /api/botusers/113/
WARNING:django.request:Forbidden: /api/analytics_data/113/
WARNING:django.request:Forbidden: /api/analytics_data/113/
WARNING:django.request:Forbidden: /api/botusers/113/
WARNING:django.request:Forbidden: /api/compaign_list/113/
WARNING:django.request:Forbidden: /api/botusers/113/
WARNING:django.request:Forbidden: /api/analytics_data/113/
WARNING:django.request:Forbidden: /api/analytics_data/113/
WARNING:django.request:Forbidden: /api/botusers/113/
WARNING:django.request:Forbidden: /api/compaign_list/113/
WARNING:django.request:Forbidden: /api/botusers/113/
WARNING:django.request:Forbidden: /api/botusers/113/
WARNING:django.request:Forbidden: /api/analytics_data/116/
WARNING:django.request:Forbidden: /api/botusers/116/
WARNING:django.request:Forbidden: /api/compaign_list/116/
WARNING:django.request:Forbidden: /api/compaign_list/116/
WARNING:django.request:Forbidden: /api/compaign_list/116/
WARNING:django.request:Forbidden: /api/botusers/116/
WARNING:django.request:Forbidden: /api/analytics_data/116/
WARNING:django.request:Forbidden: /api/compaign_list/116/
WARNING:django.request:Forbidden: /api/botusers/116/
WARNING:django.request:Forbidden: /api/analytics_data/116/
ERROR:root:TariffView <class 'AttributeError'> views.py 407 
 'NoneType' object has no attribute 'strftime'
ERROR:root:TariffView <class 'AttributeError'> views.py 407 
 'NoneType' object has no attribute 'strftime'
ERROR:root:TariffView <class 'AttributeError'> views.py 407 
 'NoneType' object has no attribute 'strftime'
ERROR:root:TariffView <class 'AttributeError'> views.py 407 
 'NoneType' object has no attribute 'strftime'
WARNING:django.request:Bad Request: /api/register/
WARNING:django.request:Unauthorized: /api/token/
WARNING:django.request:Unauthorized: /api/token/
WARNING:django.request:Unauthorized: /api/token/
ERROR:root:TariffView <class 'AttributeError'> views.py 407 
 'NoneType' object has no attribute 'strftime'
WARNING:django.request:Forbidden: /api/analytics_data/119/
WARNING:django.request:Forbidden: /api/botusers/119/
WARNING:django.request:Forbidden: /api/compaign_list/119/
WARNING:django.request:Forbidden: /api/analytics_data/119/
WARNING:django.request:Forbidden: /api/botusers/119/
WARNING:django.request:Forbidden: /api/compaign_list/119/
WARNING:django.request:Forbidden (Permission denied): /admin/accounts/user/
Traceback (most recent call last):
  File "/usr/local/lib/python3.7/site-packages/django/core/handlers/exception.py", line 34, in inner
    response = get_response(request)
  File "/usr/local/lib/python3.7/site-packages/django/core/handlers/base.py", line 115, in _get_response
    response = self.process_exception_by_middleware(e, request)
  File "/usr/local/lib/python3.7/site-packages/django/core/handlers/base.py", line 113, in _get_response
    response = wrapped_callback(request, *callback_args, **callback_kwargs)
  File "/usr/local/lib/python3.7/site-packages/django/contrib/admin/options.py", line 606, in wrapper
    return self.admin_site.admin_view(view)(*args, **kwargs)
  File "/usr/local/lib/python3.7/site-packages/django/utils/decorators.py", line 142, in _wrapped_view
    response = view_func(request, *args, **kwargs)
  File "/usr/local/lib/python3.7/site-packages/django/views/decorators/cache.py", line 44, in _wrapped_view_func
    response = view_func(request, *args, **kwargs)
  File "/usr/local/lib/python3.7/site-packages/django/contrib/admin/sites.py", line 223, in inner
    return view(request, *args, **kwargs)
  File "/usr/local/lib/python3.7/site-packages/django/utils/decorators.py", line 45, in _wrapper
    return bound_method(*args, **kwargs)
  File "/usr/local/lib/python3.7/site-packages/django/utils/decorators.py", line 142, in _wrapped_view
    response = view_func(request, *args, **kwargs)
  File "/usr/local/lib/python3.7/site-packages/django/contrib/admin/options.py", line 1669, in changelist_view
    raise PermissionDenied
django.core.exceptions.PermissionDenied
WARNING:django.request:Forbidden (Permission denied): /admin/accounts/user/
Traceback (most recent call last):
  File "/usr/local/lib/python3.7/site-packages/django/core/handlers/exception.py", line 34, in inner
    response = get_response(request)
  File "/usr/local/lib/python3.7/site-packages/django/core/handlers/base.py", line 115, in _get_response
    response = self.process_exception_by_middleware(e, request)
  File "/usr/local/lib/python3.7/site-packages/django/core/handlers/base.py", line 113, in _get_response
    response = wrapped_callback(request, *callback_args, **callback_kwargs)
  File "/usr/local/lib/python3.7/site-packages/django/contrib/admin/options.py", line 606, in wrapper
    return self.admin_site.admin_view(view)(*args, **kwargs)
  File "/usr/local/lib/python3.7/site-packages/django/utils/decorators.py", line 142, in _wrapped_view
    response = view_func(request, *args, **kwargs)
  File "/usr/local/lib/python3.7/site-packages/django/views/decorators/cache.py", line 44, in _wrapped_view_func
    response = view_func(request, *args, **kwargs)
  File "/usr/local/lib/python3.7/site-packages/django/contrib/admin/sites.py", line 223, in inner
    return view(request, *args, **kwargs)
  File "/usr/local/lib/python3.7/site-packages/django/utils/decorators.py", line 45, in _wrapper
    return bound_method(*args, **kwargs)
  File "/usr/local/lib/python3.7/site-packages/django/utils/decorators.py", line 142, in _wrapped_view
    response = view_func(request, *args, **kwargs)
  File "/usr/local/lib/python3.7/site-packages/django/contrib/admin/options.py", line 1669, in changelist_view
    raise PermissionDenied
django.core.exceptions.PermissionDenied
WARNING:django.request:Forbidden (Permission denied): /admin/accounts/user/1/change/
Traceback (most recent call last):
  File "/usr/local/lib/python3.7/site-packages/django/core/handlers/exception.py", line 34, in inner
    response = get_response(request)
  File "/usr/local/lib/python3.7/site-packages/django/core/handlers/base.py", line 115, in _get_response
    response = self.process_exception_by_middleware(e, request)
  File "/usr/local/lib/python3.7/site-packages/django/core/handlers/base.py", line 113, in _get_response
    response = wrapped_callback(request, *callback_args, **callback_kwargs)
  File "/usr/local/lib/python3.7/site-packages/django/contrib/admin/options.py", line 606, in wrapper
    return self.admin_site.admin_view(view)(*args, **kwargs)
  File "/usr/local/lib/python3.7/site-packages/django/utils/decorators.py", line 142, in _wrapped_view
    response = view_func(request, *args, **kwargs)
  File "/usr/local/lib/python3.7/site-packages/django/views/decorators/cache.py", line 44, in _wrapped_view_func
    response = view_func(request, *args, **kwargs)
  File "/usr/local/lib/python3.7/site-packages/django/contrib/admin/sites.py", line 223, in inner
    return view(request, *args, **kwargs)
  File "/usr/local/lib/python3.7/site-packages/django/contrib/admin/options.py", line 1637, in change_view
    return self.changeform_view(request, object_id, form_url, extra_context)
  File "/usr/local/lib/python3.7/site-packages/django/utils/decorators.py", line 45, in _wrapper
    return bound_method(*args, **kwargs)
  File "/usr/local/lib/python3.7/site-packages/django/utils/decorators.py", line 142, in _wrapped_view
    response = view_func(request, *args, **kwargs)
  File "/usr/local/lib/python3.7/site-packages/django/contrib/admin/options.py", line 1522, in changeform_view
    return self._changeform_view(request, object_id, form_url, extra_context)
  File "/usr/local/lib/python3.7/site-packages/django/contrib/admin/options.py", line 1546, in _changeform_view
    raise PermissionDenied
django.core.exceptions.PermissionDenied
WARNING:django.request:Forbidden: /api/analytics_data/119/
WARNING:django.request:Forbidden: /api/botusers/119/
WARNING:django.request:Forbidden: /api/compaign_list/119/
WARNING:django.request:Forbidden: /api/analytics_data/119/
WARNING:django.request:Forbidden: /api/botusers/119/
WARNING:django.request:Forbidden: /api/compaign_list/119/
WARNING:django.request:Unauthorized: /api/token/
WARNING:django.request:Unauthorized: /api/token/
WARNING:django.request:Unauthorized: /api/token/
WARNING:django.request:Forbidden: /api/analytics_data/111/
WARNING:django.request:Forbidden: /api/compaign_list/111/
WARNING:django.request:Forbidden: /api/botusers/111/
WARNING:django.request:Forbidden: /api/analytics_data/111/
WARNING:django.request:Forbidden: /api/analytics_data/111/
WARNING:django.request:Not Found: /api/bot_data/114/
WARNING:django.request:Forbidden: /api/compaign_list/116/
WARNING:django.request:Forbidden: /api/botusers/116/
WARNING:django.request:Forbidden: /api/analytics_data/116/
WARNING:django.request:Forbidden: /api/analytics_data/116/
WARNING:django.request:Forbidden: /api/analytics_data/116/
WARNING:django.request:Forbidden: /api/analytics_data/116/
WARNING:django.request:Forbidden: /api/analytics_data/116/
WARNING:django.request:Forbidden: /api/botusers/116/
WARNING:django.request:Forbidden: /api/compaign_list/116/
WARNING:django.request:Forbidden: /api/analytics_data/116/
WARNING:django.request:Forbidden: /api/analytics_data/116/
WARNING:django.request:Forbidden: /api/botusers/116/
WARNING:django.request:Forbidden: /api/compaign_list/116/
WARNING:django.request:Forbidden: /api/analytics_data/116/
WARNING:django.request:Forbidden: /api/botusers/116/
WARNING:django.request:Forbidden: /api/analytics_data/116/
WARNING:django.request:Forbidden: /api/botusers/116/
WARNING:django.request:Forbidden: /api/compaign_list/116/
WARNING:django.request:Forbidden: /api/compaign_list/111/
WARNING:django.request:Forbidden: /api/compaign_list/111/
WARNING:django.request:Forbidden: /api/compaign_list/111/
WARNING:django.request:Forbidden: /api/analytics_data/111/
WARNING:django.request:Forbidden: /api/analytics_data/111/
WARNING:django.request:Forbidden: /api/analytics_data/111/
WARNING:django.request:Forbidden: /api/botusers/111/
WARNING:django.request:Forbidden: /api/compaign_list/111/
WARNING:django.request:Forbidden: /api/analytics_data/111/
WARNING:django.request:Forbidden: /api/analytics_data/111/
WARNING:django.request:Forbidden: /api/analytics_data/111/
WARNING:django.request:Forbidden: /api/analytics_data/111/
WARNING:django.request:Forbidden: /api/botusers/111/
WARNING:django.request:Forbidden: /api/compaign_list/111/
WARNING:django.request:Forbidden: /api/analytics_data/111/
WARNING:django.request:Forbidden: /api/analytics_data/111/
WARNING:django.request:Forbidden: /api/botusers/111/
WARNING:django.request:Forbidden: /api/compaign_list/111/
ERROR:root:b'TransactionId=179026028&Amount=1.00&Currency=RUB&PaymentAmount=1.00&PaymentCurrency=RUB&OperationType=Payment&InvoiceId=15643945647134&AccountId=orlan_mh94%40mail.ru&SubscriptionId=sc_facb0e3d678bcf0b01ba8860069a6&Name=MOMENTUM+R&Email=orlan_mh94%40mail.ru&DateTime=2019-07-29+10%3a03%3a49&IpAddress=188.255.56.39&IpCountry=RU&IpCity=%d0%9c%d0%be%d1%81%d0%ba%d0%b2%d0%b0&IpRegion=%d0%9c%d0%be%d1%81%d0%ba%d0%b2%d0%b0&IpDistrict=%d0%a6%d0%b5%d0%bd%d1%82%d1%80%d0%b0%d0%bb%d1%8c%d0%bd%d1%8b%d0%b9+%d1%84%d0%b5%d0%b4%d0%b5%d1%80%d0%b0%d0%bb%d1%8c%d0%bd%d1%8b%d0%b9+%d0%be%d0%ba%d1%80%d1%83%d0%b3&IpLatitude=55.755787&IpLongitude=37.617634&CardFirstSix=533669&CardLastFour=7481&CardType=MasterCard&CardExpDate=08%2f21&Issuer=SBERBANK+OF+RUSSIA&IssuerBankCountry=RU&Description=%d0%95%d0%b6%d0%b5%d0%bc%d0%b5%d1%81%d1%8f%d1%87%d0%bd%d0%b0%d1%8f+%d0%bf%d0%be%d0%b4%d0%bf%d0%b8%d1%81%d0%ba%d0%b0+%d0%bd%d0%b0+%d1%82%d0%b0%d1%80%d0%b8%d1%84+Business+%d0%ba+%d0%b1%d0%be%d1%82%d1%83+TEST(id%3d111)%2c+inbot24.ru&AuthCode=244527&Token=540254574&TestMode=0&Status=Completed&GatewayName=Tinkoff&Data=%7b%22bot_id%22%3a111%2c%22cloudPayments%22%3a%7b%22recurrent%22%3a%7b%22interval%22%3a%22Month%22%2c%22period%22%3a1%7d%7d%7d&TotalFee=0.04&CardProduct=MCS'
WARNING:django.request:Forbidden: /api/compaign_list/119/
WARNING:django.request:Forbidden: /api/botusers/119/
WARNING:django.request:Forbidden: /api/analytics_data/119/
WARNING:django.request:Forbidden: /api/analytics_data/119/
ERROR:django.request:Internal Server Error: /admin/cabinet/payment/
Traceback (most recent call last):
  File "/usr/local/lib/python3.7/site-packages/django/core/handlers/exception.py", line 34, in inner
    response = get_response(request)
  File "/usr/local/lib/python3.7/site-packages/django/core/handlers/base.py", line 145, in _get_response
    response = self.process_exception_by_middleware(e, request)
  File "/usr/local/lib/python3.7/site-packages/django/core/handlers/base.py", line 143, in _get_response
    response = response.render()
  File "/usr/local/lib/python3.7/site-packages/django/template/response.py", line 106, in render
    self.content = self.rendered_content
  File "/usr/local/lib/python3.7/site-packages/django/template/response.py", line 83, in rendered_content
    content = template.render(context, self._request)
  File "/usr/local/lib/python3.7/site-packages/django/template/backends/django.py", line 61, in render
    return self.template.render(context)
  File "/usr/local/lib/python3.7/site-packages/django/template/base.py", line 171, in render
    return self._render(context)
  File "/usr/local/lib/python3.7/site-packages/django/template/base.py", line 163, in _render
    return self.nodelist.render(context)
  File "/usr/local/lib/python3.7/site-packages/django/template/base.py", line 937, in render
    bit = node.render_annotated(context)
  File "/usr/local/lib/python3.7/site-packages/django/template/base.py", line 904, in render_annotated
    return self.render(context)
  File "/usr/local/lib/python3.7/site-packages/django/template/loader_tags.py", line 150, in render
    return compiled_parent._render(context)
  File "/usr/local/lib/python3.7/site-packages/django/template/base.py", line 163, in _render
    return self.nodelist.render(context)
  File "/usr/local/lib/python3.7/site-packages/django/template/base.py", line 937, in render
    bit = node.render_annotated(context)
  File "/usr/local/lib/python3.7/site-packages/django/template/base.py", line 904, in render_annotated
    return self.render(context)
  File "/usr/local/lib/python3.7/site-packages/django/template/loader_tags.py", line 150, in render
    return compiled_parent._render(context)
  File "/usr/local/lib/python3.7/site-packages/django/template/base.py", line 163, in _render
    return self.nodelist.render(context)
  File "/usr/local/lib/python3.7/site-packages/django/template/base.py", line 937, in render
    bit = node.render_annotated(context)
  File "/usr/local/lib/python3.7/site-packages/django/template/base.py", line 904, in render_annotated
    return self.render(context)
  File "/usr/local/lib/python3.7/site-packages/django/template/loader_tags.py", line 62, in render
    result = block.nodelist.render(context)
  File "/usr/local/lib/python3.7/site-packages/django/template/base.py", line 937, in render
    bit = node.render_annotated(context)
  File "/usr/local/lib/python3.7/site-packages/django/template/base.py", line 904, in render_annotated
    return self.render(context)
  File "/usr/local/lib/python3.7/site-packages/django/template/loader_tags.py", line 62, in render
    result = block.nodelist.render(context)
  File "/usr/local/lib/python3.7/site-packages/django/template/base.py", line 937, in render
    bit = node.render_annotated(context)
  File "/usr/local/lib/python3.7/site-packages/django/template/base.py", line 904, in render_annotated
    return self.render(context)
  File "/usr/local/lib/python3.7/site-packages/django/contrib/admin/templatetags/base.py", line 33, in render
    return super().render(context)
  File "/usr/local/lib/python3.7/site-packages/django/template/library.py", line 214, in render
    _dict = self.func(*resolved_args, **resolved_kwargs)
  File "/usr/local/lib/python3.7/site-packages/django/contrib/admin/templatetags/admin_list.py", line 339, in result_list
    'results': list(results(cl)),
  File "/usr/local/lib/python3.7/site-packages/django/contrib/admin/templatetags/admin_list.py", line 315, in results
    yield ResultList(None, items_for_result(cl, res, None))
  File "/usr/local/lib/python3.7/site-packages/django/contrib/admin/templatetags/admin_list.py", line 306, in __init__
    super().__init__(*items)
  File "/usr/local/lib/python3.7/site-packages/django/contrib/admin/templatetags/admin_list.py", line 252, in items_for_result
    if str(result_repr) == '':
  File "/botproject/cabinet/models.py", line 178, in __str__
    return self.name
AttributeError: 'Subscription' object has no attribute 'name'
ERROR:django.request:Internal Server Error: /admin/cabinet/payment/
Traceback (most recent call last):
  File "/usr/local/lib/python3.7/site-packages/django/core/handlers/exception.py", line 34, in inner
    response = get_response(request)
  File "/usr/local/lib/python3.7/site-packages/django/core/handlers/base.py", line 145, in _get_response
    response = self.process_exception_by_middleware(e, request)
  File "/usr/local/lib/python3.7/site-packages/django/core/handlers/base.py", line 143, in _get_response
    response = response.render()
  File "/usr/local/lib/python3.7/site-packages/django/template/response.py", line 106, in render
    self.content = self.rendered_content
  File "/usr/local/lib/python3.7/site-packages/django/template/response.py", line 83, in rendered_content
    content = template.render(context, self._request)
  File "/usr/local/lib/python3.7/site-packages/django/template/backends/django.py", line 61, in render
    return self.template.render(context)
  File "/usr/local/lib/python3.7/site-packages/django/template/base.py", line 171, in render
    return self._render(context)
  File "/usr/local/lib/python3.7/site-packages/django/template/base.py", line 163, in _render
    return self.nodelist.render(context)
  File "/usr/local/lib/python3.7/site-packages/django/template/base.py", line 937, in render
    bit = node.render_annotated(context)
  File "/usr/local/lib/python3.7/site-packages/django/template/base.py", line 904, in render_annotated
    return self.render(context)
  File "/usr/local/lib/python3.7/site-packages/django/template/loader_tags.py", line 150, in render
    return compiled_parent._render(context)
  File "/usr/local/lib/python3.7/site-packages/django/template/base.py", line 163, in _render
    return self.nodelist.render(context)
  File "/usr/local/lib/python3.7/site-packages/django/template/base.py", line 937, in render
    bit = node.render_annotated(context)
  File "/usr/local/lib/python3.7/site-packages/django/template/base.py", line 904, in render_annotated
    return self.render(context)
  File "/usr/local/lib/python3.7/site-packages/django/template/loader_tags.py", line 150, in render
    return compiled_parent._render(context)
  File "/usr/local/lib/python3.7/site-packages/django/template/base.py", line 163, in _render
    return self.nodelist.render(context)
  File "/usr/local/lib/python3.7/site-packages/django/template/base.py", line 937, in render
    bit = node.render_annotated(context)
  File "/usr/local/lib/python3.7/site-packages/django/template/base.py", line 904, in render_annotated
    return self.render(context)
  File "/usr/local/lib/python3.7/site-packages/django/template/loader_tags.py", line 62, in render
    result = block.nodelist.render(context)
  File "/usr/local/lib/python3.7/site-packages/django/template/base.py", line 937, in render
    bit = node.render_annotated(context)
  File "/usr/local/lib/python3.7/site-packages/django/template/base.py", line 904, in render_annotated
    return self.render(context)
  File "/usr/local/lib/python3.7/site-packages/django/template/loader_tags.py", line 62, in render
    result = block.nodelist.render(context)
  File "/usr/local/lib/python3.7/site-packages/django/template/base.py", line 937, in render
    bit = node.render_annotated(context)
  File "/usr/local/lib/python3.7/site-packages/django/template/base.py", line 904, in render_annotated
    return self.render(context)
  File "/usr/local/lib/python3.7/site-packages/django/contrib/admin/templatetags/base.py", line 33, in render
    return super().render(context)
  File "/usr/local/lib/python3.7/site-packages/django/template/library.py", line 214, in render
    _dict = self.func(*resolved_args, **resolved_kwargs)
  File "/usr/local/lib/python3.7/site-packages/django/contrib/admin/templatetags/admin_list.py", line 339, in result_list
    'results': list(results(cl)),
  File "/usr/local/lib/python3.7/site-packages/django/contrib/admin/templatetags/admin_list.py", line 315, in results
    yield ResultList(None, items_for_result(cl, res, None))
  File "/usr/local/lib/python3.7/site-packages/django/contrib/admin/templatetags/admin_list.py", line 306, in __init__
    super().__init__(*items)
  File "/usr/local/lib/python3.7/site-packages/django/contrib/admin/templatetags/admin_list.py", line 252, in items_for_result
    if str(result_repr) == '':
  File "/botproject/cabinet/models.py", line 178, in __str__
    return self.name
AttributeError: 'Subscription' object has no attribute 'name'
ERROR:django.request:Internal Server Error: /admin/cabinet/payment/
Traceback (most recent call last):
  File "/usr/local/lib/python3.7/site-packages/django/core/handlers/exception.py", line 34, in inner
    response = get_response(request)
  File "/usr/local/lib/python3.7/site-packages/django/core/handlers/base.py", line 145, in _get_response
    response = self.process_exception_by_middleware(e, request)
  File "/usr/local/lib/python3.7/site-packages/django/core/handlers/base.py", line 143, in _get_response
    response = response.render()
  File "/usr/local/lib/python3.7/site-packages/django/template/response.py", line 106, in render
    self.content = self.rendered_content
  File "/usr/local/lib/python3.7/site-packages/django/template/response.py", line 83, in rendered_content
    content = template.render(context, self._request)
  File "/usr/local/lib/python3.7/site-packages/django/template/backends/django.py", line 61, in render
    return self.template.render(context)
  File "/usr/local/lib/python3.7/site-packages/django/template/base.py", line 171, in render
    return self._render(context)
  File "/usr/local/lib/python3.7/site-packages/django/template/base.py", line 163, in _render
    return self.nodelist.render(context)
  File "/usr/local/lib/python3.7/site-packages/django/template/base.py", line 937, in render
    bit = node.render_annotated(context)
  File "/usr/local/lib/python3.7/site-packages/django/template/base.py", line 904, in render_annotated
    return self.render(context)
  File "/usr/local/lib/python3.7/site-packages/django/template/loader_tags.py", line 150, in render
    return compiled_parent._render(context)
  File "/usr/local/lib/python3.7/site-packages/django/template/base.py", line 163, in _render
    return self.nodelist.render(context)
  File "/usr/local/lib/python3.7/site-packages/django/template/base.py", line 937, in render
    bit = node.render_annotated(context)
  File "/usr/local/lib/python3.7/site-packages/django/template/base.py", line 904, in render_annotated
    return self.render(context)
  File "/usr/local/lib/python3.7/site-packages/django/template/loader_tags.py", line 150, in render
    return compiled_parent._render(context)
  File "/usr/local/lib/python3.7/site-packages/django/template/base.py", line 163, in _render
    return self.nodelist.render(context)
  File "/usr/local/lib/python3.7/site-packages/django/template/base.py", line 937, in render
    bit = node.render_annotated(context)
  File "/usr/local/lib/python3.7/site-packages/django/template/base.py", line 904, in render_annotated
    return self.render(context)
  File "/usr/local/lib/python3.7/site-packages/django/template/loader_tags.py", line 62, in render
    result = block.nodelist.render(context)
  File "/usr/local/lib/python3.7/site-packages/django/template/base.py", line 937, in render
    bit = node.render_annotated(context)
  File "/usr/local/lib/python3.7/site-packages/django/template/base.py", line 904, in render_annotated
    return self.render(context)
  File "/usr/local/lib/python3.7/site-packages/django/template/loader_tags.py", line 62, in render
    result = block.nodelist.render(context)
  File "/usr/local/lib/python3.7/site-packages/django/template/base.py", line 937, in render
    bit = node.render_annotated(context)
  File "/usr/local/lib/python3.7/site-packages/django/template/base.py", line 904, in render_annotated
    return self.render(context)
  File "/usr/local/lib/python3.7/site-packages/django/contrib/admin/templatetags/base.py", line 33, in render
    return super().render(context)
  File "/usr/local/lib/python3.7/site-packages/django/template/library.py", line 214, in render
    _dict = self.func(*resolved_args, **resolved_kwargs)
  File "/usr/local/lib/python3.7/site-packages/django/contrib/admin/templatetags/admin_list.py", line 339, in result_list
    'results': list(results(cl)),
  File "/usr/local/lib/python3.7/site-packages/django/contrib/admin/templatetags/admin_list.py", line 315, in results
    yield ResultList(None, items_for_result(cl, res, None))
  File "/usr/local/lib/python3.7/site-packages/django/contrib/admin/templatetags/admin_list.py", line 306, in __init__
    super().__init__(*items)
  File "/usr/local/lib/python3.7/site-packages/django/contrib/admin/templatetags/admin_list.py", line 252, in items_for_result
    if str(result_repr) == '':
  File "/botproject/cabinet/models.py", line 178, in __str__
    return self.name
AttributeError: 'Subscription' object has no attribute 'name'
ERROR:django.request:Internal Server Error: /admin/cabinet/payment/
Traceback (most recent call last):
  File "/usr/local/lib/python3.7/site-packages/django/core/handlers/exception.py", line 34, in inner
    response = get_response(request)
  File "/usr/local/lib/python3.7/site-packages/django/core/handlers/base.py", line 145, in _get_response
    response = self.process_exception_by_middleware(e, request)
  File "/usr/local/lib/python3.7/site-packages/django/core/handlers/base.py", line 143, in _get_response
    response = response.render()
  File "/usr/local/lib/python3.7/site-packages/django/template/response.py", line 106, in render
    self.content = self.rendered_content
  File "/usr/local/lib/python3.7/site-packages/django/template/response.py", line 83, in rendered_content
    content = template.render(context, self._request)
  File "/usr/local/lib/python3.7/site-packages/django/template/backends/django.py", line 61, in render
    return self.template.render(context)
  File "/usr/local/lib/python3.7/site-packages/django/template/base.py", line 171, in render
    return self._render(context)
  File "/usr/local/lib/python3.7/site-packages/django/template/base.py", line 163, in _render
    return self.nodelist.render(context)
  File "/usr/local/lib/python3.7/site-packages/django/template/base.py", line 937, in render
    bit = node.render_annotated(context)
  File "/usr/local/lib/python3.7/site-packages/django/template/base.py", line 904, in render_annotated
    return self.render(context)
  File "/usr/local/lib/python3.7/site-packages/django/template/loader_tags.py", line 150, in render
    return compiled_parent._render(context)
  File "/usr/local/lib/python3.7/site-packages/django/template/base.py", line 163, in _render
    return self.nodelist.render(context)
  File "/usr/local/lib/python3.7/site-packages/django/template/base.py", line 937, in render
    bit = node.render_annotated(context)
  File "/usr/local/lib/python3.7/site-packages/django/template/base.py", line 904, in render_annotated
    return self.render(context)
  File "/usr/local/lib/python3.7/site-packages/django/template/loader_tags.py", line 150, in render
    return compiled_parent._render(context)
  File "/usr/local/lib/python3.7/site-packages/django/template/base.py", line 163, in _render
    return self.nodelist.render(context)
  File "/usr/local/lib/python3.7/site-packages/django/template/base.py", line 937, in render
    bit = node.render_annotated(context)
  File "/usr/local/lib/python3.7/site-packages/django/template/base.py", line 904, in render_annotated
    return self.render(context)
  File "/usr/local/lib/python3.7/site-packages/django/template/loader_tags.py", line 62, in render
    result = block.nodelist.render(context)
  File "/usr/local/lib/python3.7/site-packages/django/template/base.py", line 937, in render
    bit = node.render_annotated(context)
  File "/usr/local/lib/python3.7/site-packages/django/template/base.py", line 904, in render_annotated
    return self.render(context)
  File "/usr/local/lib/python3.7/site-packages/django/template/loader_tags.py", line 62, in render
    result = block.nodelist.render(context)
  File "/usr/local/lib/python3.7/site-packages/django/template/base.py", line 937, in render
    bit = node.render_annotated(context)
  File "/usr/local/lib/python3.7/site-packages/django/template/base.py", line 904, in render_annotated
    return self.render(context)
  File "/usr/local/lib/python3.7/site-packages/django/contrib/admin/templatetags/base.py", line 33, in render
    return super().render(context)
  File "/usr/local/lib/python3.7/site-packages/django/template/library.py", line 214, in render
    _dict = self.func(*resolved_args, **resolved_kwargs)
  File "/usr/local/lib/python3.7/site-packages/django/contrib/admin/templatetags/admin_list.py", line 339, in result_list
    'results': list(results(cl)),
  File "/usr/local/lib/python3.7/site-packages/django/contrib/admin/templatetags/admin_list.py", line 315, in results
    yield ResultList(None, items_for_result(cl, res, None))
  File "/usr/local/lib/python3.7/site-packages/django/contrib/admin/templatetags/admin_list.py", line 306, in __init__
    super().__init__(*items)
  File "/usr/local/lib/python3.7/site-packages/django/contrib/admin/templatetags/admin_list.py", line 252, in items_for_result
    if str(result_repr) == '':
  File "/botproject/cabinet/models.py", line 178, in __str__
    return self.name
AttributeError: 'Subscription' object has no attribute 'name'
WARNING:django.request:Unauthorized: /api/bot_list/
WARNING:django.request:Unauthorized: /api/bot_data/111/
WARNING:django.request:Unauthorized: /api/analytics_data/111/
WARNING:django.request:Unauthorized: /api/tariff/111/
WARNING:django.request:Forbidden: /api/analytics_data/117/
WARNING:django.request:Forbidden: /api/analytics_data/117/
WARNING:django.request:Forbidden: /api/compaign_list/119/
WARNING:django.request:Forbidden: /api/botusers/119/
WARNING:django.request:Forbidden: /api/analytics_data/119/
WARNING:django.request:Forbidden: /api/analytics_data/116/
WARNING:django.request:Forbidden: /api/botusers/116/
WARNING:django.request:Forbidden: /api/compaign_list/116/
WARNING:django.request:Forbidden: /api/analytics_data/116/
WARNING:django.request:Forbidden: /api/analytics_data/117/
WARNING:django.request:Forbidden: /api/compaign_list/117/
WARNING:django.request:Unauthorized: /api/bot_data/111/
WARNING:django.request:Forbidden: /api/compaign_list/112/
WARNING:django.request:Forbidden: /api/botusers/112/
WARNING:django.request:Forbidden: /api/analytics_data/112/
WARNING:django.request:Forbidden: /api/analytics_data/112/
WARNING:django.request:Unauthorized: /api/bot_data/111/
WARNING:django.request:Forbidden: /api/compaign_list/112/
WARNING:django.request:Forbidden: /api/botusers/112/
WARNING:django.request:Forbidden: /api/analytics_data/112/
WARNING:django.request:Forbidden: /api/analytics_data/112/
WARNING:django.request:Forbidden: /api/botusers/112/
WARNING:django.request:Forbidden: /api/analytics_data/112/
WARNING:django.request:Forbidden: /api/botusers/112/
WARNING:django.request:Forbidden: /api/analytics_data/112/
WARNING:django.request:Forbidden: /api/compaign_list/119/
WARNING:django.request:Forbidden: /api/botusers/119/
WARNING:django.request:Forbidden: /api/analytics_data/119/
WARNING:django.request:Forbidden: /api/analytics_data/117/
WARNING:django.request:Forbidden: /api/botusers/117/
WARNING:django.request:Forbidden: /api/compaign_list/117/
WARNING:django.request:Forbidden: /api/analytics_data/120/
WARNING:django.request:Forbidden: /api/botusers/120/
WARNING:django.request:Forbidden: /api/compaign_list/120/
WARNING:django.request:Forbidden: /api/analytics_data/120/
WARNING:django.request:Forbidden: /api/compaign_list/120/
WARNING:django.request:Forbidden: /api/analytics_data/120/
WARNING:django.request:Unauthorized: /api/bot_data/111/
WARNING:django.request:Not Found: /admin/config.php
WARNING:django.request:Not Found: /admin/config.php
WARNING:django.request:Forbidden: /api/compaign_list/112/
WARNING:django.request:Forbidden: /api/botusers/112/
WARNING:django.request:Forbidden: /api/analytics_data/112/
WARNING:django.request:Forbidden: /api/botusers/112/
WARNING:django.request:Forbidden: /api/analytics_data/112/
WARNING:django.request:Forbidden: /api/compaign_list/112/
WARNING:django.request:Forbidden: /api/botusers/112/
WARNING:django.request:Forbidden: /api/analytics_data/112/
WARNING:django.request:Forbidden: /api/analytics_data/112/
WARNING:django.request:Forbidden: /api/analytics_data/112/
WARNING:django.request:Forbidden: /api/botusers/112/
WARNING:django.request:Forbidden: /api/compaign_list/112/
WARNING:django.request:Forbidden: /api/botusers/112/
WARNING:django.request:Forbidden: /api/analytics_data/112/
WARNING:django.request:Forbidden: /api/analytics_data/112/
WARNING:django.request:Forbidden: /api/analytics_data/112/
WARNING:django.request:Forbidden: /api/analytics_data/112/
WARNING:django.request:Forbidden: /api/analytics_data/112/
WARNING:django.request:Forbidden: /api/botusers/112/
WARNING:django.request:Forbidden: /api/compaign_list/112/
WARNING:django.request:Forbidden: /api/botusers/112/
WARNING:django.request:Forbidden: /api/compaign_list/112/
WARNING:django.request:Forbidden: /api/compaign_list/112/
WARNING:django.request:Forbidden: /api/botusers/112/
WARNING:django.request:Forbidden: /api/analytics_data/112/
WARNING:django.request:Forbidden: /api/analytics_data/112/
WARNING:django.request:Forbidden: /api/analytics_data/119/
WARNING:django.request:Forbidden: /api/botusers/119/
WARNING:django.request:Forbidden: /api/compaign_list/119/
WARNING:django.request:Forbidden: /api/analytics_data/119/
WARNING:django.request:Forbidden: /api/analytics_data/119/
WARNING:django.request:Forbidden: /api/botusers/119/
WARNING:django.request:Forbidden: /api/compaign_list/119/
WARNING:django.request:Bad Request: /api/analytics_data/119/
WARNING:django.request:Forbidden: /api/analytics_data/121/
WARNING:django.request:Forbidden: /api/analytics_data/123/
WARNING:django.request:Not Found: /api/bot_data/119/
WARNING:django.request:Forbidden: /api/compaign_list/116/
WARNING:django.request:Forbidden: /api/botusers/116/
WARNING:django.request:Forbidden: /api/analytics_data/116/
WARNING:django.request:Forbidden: /api/compaign_list/116/
WARNING:django.request:Forbidden: /api/botusers/116/
WARNING:django.request:Forbidden: /api/analytics_data/116/
WARNING:django.request:Not Found: /api/bot_data/112/
WARNING:django.request:Unauthorized: /api/token/
WARNING:django.request:Unauthorized: /api/token/
WARNING:django.request:Forbidden: /api/analytics_data/117/
WARNING:django.request:Forbidden: /api/analytics_data/117/
WARNING:django.request:Forbidden: /api/botusers/117/
WARNING:django.request:Forbidden: /api/compaign_list/117/
WARNING:django.request:Forbidden: /api/botusers/117/
WARNING:django.request:Forbidden: /api/analytics_data/117/
WARNING:django.request:Unauthorized: /api/bot_list/
WARNING:django.request:Forbidden: /api/compaign_list/116/
WARNING:django.request:Forbidden: /api/compaign_list/116/
WARNING:django.request:Forbidden: /api/botusers/116/
WARNING:django.request:Forbidden: /api/botusers/117/
ERROR:django.request:Internal Server Error: /admin/cabinet/payment/1/change/
Traceback (most recent call last):
  File "/usr/local/lib/python3.7/site-packages/django/core/handlers/exception.py", line 34, in inner
    response = get_response(request)
  File "/usr/local/lib/python3.7/site-packages/django/core/handlers/base.py", line 145, in _get_response
    response = self.process_exception_by_middleware(e, request)
  File "/usr/local/lib/python3.7/site-packages/django/core/handlers/base.py", line 143, in _get_response
    response = response.render()
  File "/usr/local/lib/python3.7/site-packages/django/template/response.py", line 106, in render
    self.content = self.rendered_content
  File "/usr/local/lib/python3.7/site-packages/django/template/response.py", line 83, in rendered_content
    content = template.render(context, self._request)
  File "/usr/local/lib/python3.7/site-packages/django/template/backends/django.py", line 61, in render
    return self.template.render(context)
  File "/usr/local/lib/python3.7/site-packages/django/template/base.py", line 171, in render
    return self._render(context)
  File "/usr/local/lib/python3.7/site-packages/django/template/base.py", line 163, in _render
    return self.nodelist.render(context)
  File "/usr/local/lib/python3.7/site-packages/django/template/base.py", line 937, in render
    bit = node.render_annotated(context)
  File "/usr/local/lib/python3.7/site-packages/django/template/base.py", line 904, in render_annotated
    return self.render(context)
  File "/usr/local/lib/python3.7/site-packages/django/template/loader_tags.py", line 150, in render
    return compiled_parent._render(context)
  File "/usr/local/lib/python3.7/site-packages/django/template/base.py", line 163, in _render
    return self.nodelist.render(context)
  File "/usr/local/lib/python3.7/site-packages/django/template/base.py", line 937, in render
    bit = node.render_annotated(context)
  File "/usr/local/lib/python3.7/site-packages/django/template/base.py", line 904, in render_annotated
    return self.render(context)
  File "/usr/local/lib/python3.7/site-packages/django/template/loader_tags.py", line 150, in render
    return compiled_parent._render(context)
  File "/usr/local/lib/python3.7/site-packages/django/template/base.py", line 163, in _render
    return self.nodelist.render(context)
  File "/usr/local/lib/python3.7/site-packages/django/template/base.py", line 937, in render
    bit = node.render_annotated(context)
  File "/usr/local/lib/python3.7/site-packages/django/template/base.py", line 904, in render_annotated
    return self.render(context)
  File "/usr/local/lib/python3.7/site-packages/django/template/defaulttags.py", line 309, in render
    return nodelist.render(context)
  File "/usr/local/lib/python3.7/site-packages/django/template/base.py", line 937, in render
    bit = node.render_annotated(context)
  File "/usr/local/lib/python3.7/site-packages/django/template/base.py", line 904, in render_annotated
    return self.render(context)
  File "/usr/local/lib/python3.7/site-packages/django/template/loader_tags.py", line 62, in render
    result = block.nodelist.render(context)
  File "/usr/local/lib/python3.7/site-packages/django/template/base.py", line 937, in render
    bit = node.render_annotated(context)
  File "/usr/local/lib/python3.7/site-packages/django/template/base.py", line 904, in render_annotated
    return self.render(context)
  File "/usr/local/lib/python3.7/site-packages/django/template/defaulttags.py", line 309, in render
    return nodelist.render(context)
  File "/usr/local/lib/python3.7/site-packages/django/template/base.py", line 937, in render
    bit = node.render_annotated(context)
  File "/usr/local/lib/python3.7/site-packages/django/template/base.py", line 904, in render_annotated
    return self.render(context)
  File "/usr/local/lib/python3.7/site-packages/django/template/base.py", line 987, in render
    output = self.filter_expression.resolve(context)
  File "/usr/local/lib/python3.7/site-packages/django/template/base.py", line 698, in resolve
    new_obj = func(obj, *arg_vals)
  File "/usr/local/lib/python3.7/site-packages/django/template/defaultfilters.py", line 42, in _dec
    args[0] = str(args[0])
TypeError: __str__ returned non-string (type int)
WARNING:django.request:Bad Request: /api/tariff/117/
ERROR:root:b'TransactionId=183121677&Amount=1.00&Currency=RUB&PaymentAmount=1.00&PaymentCurrency=RUB&OperationType=Payment&InvoiceId=15650890239663&AccountId=nurarip%40yandex.ru&SubscriptionId=sc_1422987a13cc6d89c5ac709ea974a&Name=ARIP+NURMAGOMEDOV&Email=nurarip%40yandex.ru&DateTime=2019-08-06+10%3a58%3a01&IpAddress=212.118.63.191&IpCountry=RU&IpCity=%d0%9c%d0%be%d1%81%d0%ba%d0%b2%d0%b0&IpRegion=%d0%9c%d0%be%d1%81%d0%ba%d0%b2%d0%b0&IpDistrict=%d0%a6%d0%b5%d0%bd%d1%82%d1%80%d0%b0%d0%bb%d1%8c%d0%bd%d1%8b%d0%b9+%d1%84%d0%b5%d0%b4%d0%b5%d1%80%d0%b0%d0%bb%d1%8c%d0%bd%d1%8b%d0%b9+%d0%be%d0%ba%d1%80%d1%83%d0%b3&IpLatitude=55.755787&IpLongitude=37.617634&CardFirstSix=521324&CardLastFour=0913&CardType=MasterCard&CardExpDate=04%2f21&Issuer=TINKOFF+BANK&IssuerBankCountry=RU&Description=%d0%95%d0%b6%d0%b5%d0%bc%d0%b5%d1%81%d1%8f%d1%87%d0%bd%d0%b0%d1%8f+%d0%bf%d0%be%d0%b4%d0%bf%d0%b8%d1%81%d0%ba%d0%b0+%d0%bd%d0%b0+%d1%82%d0%b0%d1%80%d0%b8%d1%84+Business+%d0%ba+%d0%b1%d0%be%d1%82%d1%83+Test(id%3d116)%2c+inbot24.ru&AuthCode=084520&Token=543011578&TestMode=0&Status=Completed&GatewayName=Tinkoff&Data=%7b%22bot_id%22%3a116%2c%22cloudPayments%22%3a%7b%22recurrent%22%3a%7b%22interval%22%3a%22Month%22%2c%22period%22%3a1%7d%7d%7d&TotalFee=0.04&CardProduct=MNW'
WARNING:django.request:Not Found: /admin//config.php
WARNING:django.request:Forbidden: /api/analytics_data/124/
WARNING:django.request:Forbidden: /api/compaign_list/125/
WARNING:django.request:Forbidden: /api/botusers/125/
WARNING:django.request:Forbidden: /api/analytics_data/125/
WARNING:django.request:Unauthorized: /api/token/
WARNING:django.request:Unauthorized: /api/token/
WARNING:django.request:Unauthorized: /api/token/
WARNING:django.request:Unauthorized: /api/token/
WARNING:django.request:Unauthorized: /api/token/
WARNING:django.request:Unauthorized: /api/token/
WARNING:django.request:Unauthorized: /api/token/
WARNING:django.request:Forbidden: /api/analytics_data/130/
ERROR:root:b'TransactionId=187520549&Amount=1.00&Currency=RUB&PaymentAmount=1.00&PaymentCurrency=RUB&OperationType=Payment&InvoiceId=15657876223624&AccountId=amonystudio%40gmail.com&SubscriptionId=sc_e23fd949db296c6d4bcd3eefe21f8&Name=AYRAT+TONDUVAY&Email=amonystudio%40gmail.com&DateTime=2019-08-14+13%3a01%3a34&IpAddress=176.59.49.109&IpCountry=RU&IpCity=%d0%9c%d0%be%d1%81%d0%ba%d0%b2%d0%b0&IpRegion=%d0%9c%d0%be%d1%81%d0%ba%d0%b2%d0%b0&IpDistrict=%d0%a6%d0%b5%d0%bd%d1%82%d1%80%d0%b0%d0%bb%d1%8c%d0%bd%d1%8b%d0%b9+%d1%84%d0%b5%d0%b4%d0%b5%d1%80%d0%b0%d0%bb%d1%8c%d0%bd%d1%8b%d0%b9+%d0%be%d0%ba%d1%80%d1%83%d0%b3&IpLatitude=55.755787&IpLongitude=37.617634&CardFirstSix=427631&CardLastFour=3783&CardType=Visa&CardExpDate=10%2f21&Issuer=SBERBANK+of+Russia&IssuerBankCountry=RU&Description=%d0%95%d0%b6%d0%b5%d0%bc%d0%b5%d1%81%d1%8f%d1%87%d0%bd%d0%b0%d1%8f+%d0%bf%d0%be%d0%b4%d0%bf%d0%b8%d1%81%d0%ba%d0%b0+%d0%bd%d0%b0+%d1%82%d0%b0%d1%80%d0%b8%d1%84+Business+%d0%ba+%d0%b1%d0%be%d1%82%d1%83+Amony+fit(id%3d129)%2c+inbot24.ru&AuthCode=213430&Token=545860796&TestMode=0&Status=Completed&GatewayName=Tinkoff&Data=%7b%22bot_id%22%3a129%2c%22cloudPayments%22%3a%7b%22recurrent%22%3a%7b%22interval%22%3a%22Month%22%2c%22period%22%3a1%7d%7d%7d&TotalFee=0.04&CardProduct=F'
ERROR:root:b'TransactionId=187521137&Amount=1.00&Currency=RUB&PaymentAmount=1.00&PaymentCurrency=RUB&OperationType=Payment&InvoiceId=15657877394151&AccountId=amonystudio%40gmail.com&SubscriptionId=sc_17a524757e366c1883d1d84cb027a&Name=AYRAT+TONDUVAY&Email=amonystudio%40gmail.com&DateTime=2019-08-14+13%3a02%3a51&IpAddress=176.59.49.109&IpCountry=RU&IpCity=%d0%9c%d0%be%d1%81%d0%ba%d0%b2%d0%b0&IpRegion=%d0%9c%d0%be%d1%81%d0%ba%d0%b2%d0%b0&IpDistrict=%d0%a6%d0%b5%d0%bd%d1%82%d1%80%d0%b0%d0%bb%d1%8c%d0%bd%d1%8b%d0%b9+%d1%84%d0%b5%d0%b4%d0%b5%d1%80%d0%b0%d0%bb%d1%8c%d0%bd%d1%8b%d0%b9+%d0%be%d0%ba%d1%80%d1%83%d0%b3&IpLatitude=55.755787&IpLongitude=37.617634&CardFirstSix=427631&CardLastFour=3783&CardType=Visa&CardExpDate=10%2f21&Issuer=SBERBANK+of+Russia&IssuerBankCountry=RU&Description=%d0%95%d0%b6%d0%b5%d0%bc%d0%b5%d1%81%d1%8f%d1%87%d0%bd%d0%b0%d1%8f+%d0%bf%d0%be%d0%b4%d0%bf%d0%b8%d1%81%d0%ba%d0%b0+%d0%bd%d0%b0+%d1%82%d0%b0%d1%80%d0%b8%d1%84+Business+%d0%ba+%d0%b1%d0%be%d1%82%d1%83+Amony+beauty(id%3d131)%2c+inbot24.ru&AuthCode=237144&Token=545861268&TestMode=0&Status=Completed&GatewayName=Tinkoff&Data=%7b%22bot_id%22%3a131%2c%22cloudPayments%22%3a%7b%22recurrent%22%3a%7b%22interval%22%3a%22Month%22%2c%22period%22%3a1%7d%7d%7d&TotalFee=0.04&CardProduct=F'
WARNING:django.request:Forbidden: /api/analytics_data/130/
WARNING:django.request:Forbidden: /api/botusers/130/
WARNING:django.request:Forbidden: /api/compaign_list/130/
WARNING:django.request:Forbidden: /api/compaign_list/130/
WARNING:django.request:Forbidden: /api/botusers/130/
WARNING:django.request:Forbidden: /api/analytics_data/130/
WARNING:django.request:Forbidden: /api/analytics_data/130/
WARNING:django.request:Forbidden: /api/analytics_data/130/
WARNING:django.request:Forbidden: /api/analytics_data/130/
WARNING:django.request:Forbidden: /api/analytics_data/130/
WARNING:django.request:Unauthorized: /api/token/
WARNING:django.request:Unauthorized: /api/token/
WARNING:django.request:Unauthorized: /api/token/
WARNING:django.request:Unauthorized: /api/token/
WARNING:django.request:Forbidden: /api/botusers/132/
WARNING:django.request:Forbidden: /api/compaign_list/132/
ERROR:root:b'TransactionId=188450820&Amount=1199.00&Currency=RUB&PaymentAmount=1199.00&PaymentCurrency=RUB&OperationType=Payment&InvoiceId=15659359666591&AccountId=Takeme.studio%40mail.ru&SubscriptionId=sc_401bab676ff79052c88d2793699b5&Name=ARYA+BADMAZHAPOVA&Email=takeme.studio%40mail.ru&DateTime=2019-08-16+06%3a13%3a07&IpAddress=176.59.37.163&IpCountry=RU&IpCity=%d0%9c%d0%be%d1%81%d0%ba%d0%b2%d0%b0&IpRegion=%d0%9c%d0%be%d1%81%d0%ba%d0%b2%d0%b0&IpDistrict=%d0%a6%d0%b5%d0%bd%d1%82%d1%80%d0%b0%d0%bb%d1%8c%d0%bd%d1%8b%d0%b9+%d1%84%d0%b5%d0%b4%d0%b5%d1%80%d0%b0%d0%bb%d1%8c%d0%bd%d1%8b%d0%b9+%d0%be%d0%ba%d1%80%d1%83%d0%b3&IpLatitude=55.755787&IpLongitude=37.617634&CardFirstSix=546938&CardLastFour=5727&CardType=MasterCard&CardExpDate=02%2f22&Issuer=SBERBANK+OF+RUSSIA&IssuerBankCountry=RU&Description=%d0%95%d0%b6%d0%b5%d0%bc%d0%b5%d1%81%d1%8f%d1%87%d0%bd%d0%b0%d1%8f+%d0%bf%d0%be%d0%b4%d0%bf%d0%b8%d1%81%d0%ba%d0%b0+%d0%bd%d0%b0+%d1%82%d0%b0%d1%80%d0%b8%d1%84+Business+%d0%ba+%d0%b1%d0%be%d1%82%d1%83+Takeme+Studio(id%3d132)%2c+inbot24.ru&AuthCode=223175&Token=546447094&TestMode=0&Status=Completed&GatewayName=Tinkoff&Data=%7b%22bot_id%22%3a132%2c%22cloudPayments%22%3a%7b%22recurrent%22%3a%7b%22interval%22%3a%22Month%22%2c%22period%22%3a1%7d%7d%7d&TotalFee=46.76&CardProduct=SAP'
ERROR:django.request:Internal Server Error: /admin/cabinet/payment/5/change/
Traceback (most recent call last):
  File "/usr/local/lib/python3.7/site-packages/django/core/handlers/exception.py", line 34, in inner
    response = get_response(request)
  File "/usr/local/lib/python3.7/site-packages/django/core/handlers/base.py", line 145, in _get_response
    response = self.process_exception_by_middleware(e, request)
  File "/usr/local/lib/python3.7/site-packages/django/core/handlers/base.py", line 143, in _get_response
    response = response.render()
  File "/usr/local/lib/python3.7/site-packages/django/template/response.py", line 106, in render
    self.content = self.rendered_content
  File "/usr/local/lib/python3.7/site-packages/django/template/response.py", line 83, in rendered_content
    content = template.render(context, self._request)
  File "/usr/local/lib/python3.7/site-packages/django/template/backends/django.py", line 61, in render
    return self.template.render(context)
  File "/usr/local/lib/python3.7/site-packages/django/template/base.py", line 171, in render
    return self._render(context)
  File "/usr/local/lib/python3.7/site-packages/django/template/base.py", line 163, in _render
    return self.nodelist.render(context)
  File "/usr/local/lib/python3.7/site-packages/django/template/base.py", line 937, in render
    bit = node.render_annotated(context)
  File "/usr/local/lib/python3.7/site-packages/django/template/base.py", line 904, in render_annotated
    return self.render(context)
  File "/usr/local/lib/python3.7/site-packages/django/template/loader_tags.py", line 150, in render
    return compiled_parent._render(context)
  File "/usr/local/lib/python3.7/site-packages/django/template/base.py", line 163, in _render
    return self.nodelist.render(context)
  File "/usr/local/lib/python3.7/site-packages/django/template/base.py", line 937, in render
    bit = node.render_annotated(context)
  File "/usr/local/lib/python3.7/site-packages/django/template/base.py", line 904, in render_annotated
    return self.render(context)
  File "/usr/local/lib/python3.7/site-packages/django/template/loader_tags.py", line 150, in render
    return compiled_parent._render(context)
  File "/usr/local/lib/python3.7/site-packages/django/template/base.py", line 163, in _render
    return self.nodelist.render(context)
  File "/usr/local/lib/python3.7/site-packages/django/template/base.py", line 937, in render
    bit = node.render_annotated(context)
  File "/usr/local/lib/python3.7/site-packages/django/template/base.py", line 904, in render_annotated
    return self.render(context)
  File "/usr/local/lib/python3.7/site-packages/django/template/defaulttags.py", line 309, in render
    return nodelist.render(context)
  File "/usr/local/lib/python3.7/site-packages/django/template/base.py", line 937, in render
    bit = node.render_annotated(context)
  File "/usr/local/lib/python3.7/site-packages/django/template/base.py", line 904, in render_annotated
    return self.render(context)
  File "/usr/local/lib/python3.7/site-packages/django/template/loader_tags.py", line 62, in render
    result = block.nodelist.render(context)
  File "/usr/local/lib/python3.7/site-packages/django/template/base.py", line 937, in render
    bit = node.render_annotated(context)
  File "/usr/local/lib/python3.7/site-packages/django/template/base.py", line 904, in render_annotated
    return self.render(context)
  File "/usr/local/lib/python3.7/site-packages/django/template/defaulttags.py", line 309, in render
    return nodelist.render(context)
  File "/usr/local/lib/python3.7/site-packages/django/template/base.py", line 937, in render
    bit = node.render_annotated(context)
  File "/usr/local/lib/python3.7/site-packages/django/template/base.py", line 904, in render_annotated
    return self.render(context)
  File "/usr/local/lib/python3.7/site-packages/django/template/base.py", line 987, in render
    output = self.filter_expression.resolve(context)
  File "/usr/local/lib/python3.7/site-packages/django/template/base.py", line 698, in resolve
    new_obj = func(obj, *arg_vals)
  File "/usr/local/lib/python3.7/site-packages/django/template/defaultfilters.py", line 42, in _dec
    args[0] = str(args[0])
TypeError: __str__ returned non-string (type int)
WARNING:django.request:Forbidden: /api/compaign_list/136/
WARNING:django.request:Forbidden: /api/botusers/136/
WARNING:django.request:Forbidden: /api/analytics_data/136/
WARNING:django.request:Forbidden: /api/analytics_data/136/
WARNING:django.request:Forbidden: /api/analytics_data/135/
WARNING:django.request:Forbidden: /api/botusers/135/
WARNING:django.request:Forbidden: /api/compaign_list/135/
WARNING:django.request:Unauthorized: /api/token/
WARNING:django.request:Unauthorized: /api/token/
ERROR:root:b'TransactionId=189104502&Amount=1199.00&Currency=RUB&PaymentAmount=1199.00&PaymentCurrency=RUB&OperationType=Payment&InvoiceId=15660376984430&AccountId=mergen%40irgit.net&SubscriptionId=sc_06ba33ac1c419ed0251e5913705d9&Name=MERGEN+IRGIT&Email=mergen%40irgit.net&DateTime=2019-08-17+10%3a30%3a31&IpAddress=79.139.234.155&IpCountry=RU&IpCity=%d0%9c%d0%be%d1%81%d0%ba%d0%b2%d0%b0&IpRegion=%d0%9c%d0%be%d1%81%d0%ba%d0%b2%d0%b0&IpDistrict=%d0%a6%d0%b5%d0%bd%d1%82%d1%80%d0%b0%d0%bb%d1%8c%d0%bd%d1%8b%d0%b9+%d1%84%d0%b5%d0%b4%d0%b5%d1%80%d0%b0%d0%bb%d1%8c%d0%bd%d1%8b%d0%b9+%d0%be%d0%ba%d1%80%d1%83%d0%b3&IpLatitude=55.755787&IpLongitude=37.617634&CardFirstSix=555947&CardLastFour=8477&CardType=MasterCard&CardExpDate=01%2f21&Issuer=JOINT+STOCK+COMPANY+%22ALFA-BANK%22&IssuerBankCountry=RU&Description=%d0%95%d0%b6%d0%b5%d0%bc%d0%b5%d1%81%d1%8f%d1%87%d0%bd%d0%b0%d1%8f+%d0%bf%d0%be%d0%b4%d0%bf%d0%b8%d1%81%d0%ba%d0%b0+%d0%bd%d0%b0+%d1%82%d0%b0%d1%80%d0%b8%d1%84+Business+%d0%ba+%d0%b1%d0%be%d1%82%d1%83+%d0%a2%d1%8b%d0%b2%d0%b0+%d0%bc%d0%b0%d0%bd%d1%87%d1%8b(id%3d130)%2c+inbot24.ru&AuthCode=9EN5N1&Token=546879463&TestMode=0&Status=Completed&GatewayName=Tinkoff&Data=%7b%22bot_id%22%3a130%2c%22cloudPayments%22%3a%7b%22recurrent%22%3a%7b%22interval%22%3a%22Month%22%2c%22period%22%3a1%7d%7d%7d&TotalFee=46.76&CardProduct=MNW'
WARNING:django.request:Unauthorized: /api/token/
WARNING:django.request:Unauthorized: /api/token/
WARNING:django.request:Unauthorized: /api/token/
WARNING:django.request:Unauthorized: /api/token/
WARNING:django.request:Unauthorized: /api/token/
ERROR:root:b'TransactionId=189133316&Amount=1199.00&Currency=RUB&PaymentAmount=1199.00&PaymentCurrency=RUB&OperationType=Payment&InvoiceId=15660416429345&AccountId=kyzyl%40likebz.ru&SubscriptionId=sc_88d2af27b4dd8a6855d1bebc5ab16&Name=SUZUNMAA+KUZHUGET&Email=kyzyl%40likebz.ru&DateTime=2019-08-17+11%3a36%3a02&IpAddress=31.173.242.101&IpCountry=RU&IpCity=%d0%a1%d0%b0%d0%bc%d0%b0%d1%80%d0%b0&IpRegion=%d0%a1%d0%b0%d0%bc%d0%b0%d1%80%d1%81%d0%ba%d0%b0%d1%8f+%d0%be%d0%b1%d0%bb%d0%b0%d1%81%d1%82%d1%8c&IpDistrict=%d0%9f%d1%80%d0%b8%d0%b2%d0%be%d0%bb%d0%b6%d1%81%d0%ba%d0%b8%d0%b9+%d1%84%d0%b5%d0%b4%d0%b5%d1%80%d0%b0%d0%bb%d1%8c%d0%bd%d1%8b%d0%b9+%d0%be%d0%ba%d1%80%d1%83%d0%b3&IpLatitude=53.20216&IpLongitude=50.159618&CardFirstSix=427631&CardLastFour=2447&CardType=Visa&CardExpDate=03%2f22&Issuer=SBERBANK+of+Russia&IssuerBankCountry=RU&Description=%d0%95%d0%b6%d0%b5%d0%bc%d0%b5%d1%81%d1%8f%d1%87%d0%bd%d0%b0%d1%8f+%d0%bf%d0%be%d0%b4%d0%bf%d0%b8%d1%81%d0%ba%d0%b0+%d0%bd%d0%b0+%d1%82%d0%b0%d1%80%d0%b8%d1%84+Business+%d0%ba+%d0%b1%d0%be%d1%82%d1%83+like+%d1%86%d0%b5%d0%bd%d1%82%d1%80+%d0%a2%d1%8b%d0%b2%d0%b0(id%3d137)%2c+inbot24.ru&AuthCode=275017&Token=546902071&TestMode=0&Status=Completed&GatewayName=Tinkoff&Data=%7b%22bot_id%22%3a137%2c%22cloudPayments%22%3a%7b%22recurrent%22%3a%7b%22interval%22%3a%22Month%22%2c%22period%22%3a1%7d%7d%7d&TotalFee=46.76&CardProduct=F'
WARNING:django.request:Unauthorized: /api/token/
WARNING:django.request:Unauthorized: /api/token/
ERROR:root:b'TransactionId=189732103&Amount=1199.00&Currency=RUB&PaymentAmount=1199.00&PaymentCurrency=RUB&OperationType=Payment&InvoiceId=15661372966830&AccountId=natka.90.1990%40gmail.com&SubscriptionId=sc_351af8d5dc4196993d4763e3af193&Name=NATALYA+VASILENKO&Email=natka.90.1990%40gmail.com&DateTime=2019-08-18+14%3a09%3a42&IpAddress=31.173.83.238&IpCountry=RU&IpCity=%d0%9c%d0%be%d1%81%d0%ba%d0%b2%d0%b0&IpRegion=%d0%9c%d0%be%d1%81%d0%ba%d0%b2%d0%b0&IpDistrict=%d0%a6%d0%b5%d0%bd%d1%82%d1%80%d0%b0%d0%bb%d1%8c%d0%bd%d1%8b%d0%b9+%d1%84%d0%b5%d0%b4%d0%b5%d1%80%d0%b0%d0%bb%d1%8c%d0%bd%d1%8b%d0%b9+%d0%be%d0%ba%d1%80%d1%83%d0%b3&IpLatitude=55.755787&IpLongitude=37.617634&CardFirstSix=521324&CardLastFour=2576&CardType=MasterCard&CardExpDate=11%2f23&Issuer=TINKOFF+BANK&IssuerBankCountry=RU&Description=%d0%95%d0%b6%d0%b5%d0%bc%d0%b5%d1%81%d1%8f%d1%87%d0%bd%d0%b0%d1%8f+%d0%bf%d0%be%d0%b4%d0%bf%d0%b8%d1%81%d0%ba%d0%b0+%d0%bd%d0%b0+%d1%82%d0%b0%d1%80%d0%b8%d1%84+Business+%d0%ba+%d0%b1%d0%be%d1%82%d1%83+%d0%9d%d0%b0%d1%80%d0%b0%d1%89%d0%b8%d0%b2%d0%b0%d0%bd%d0%b8%d0%b5+%d1%80%d0%b5%d1%81%d0%bd%d0%b8%d1%86(id%3d139)%2c+inbot24.ru&AuthCode=010639&Token=547279521&TestMode=0&Status=Completed&GatewayName=Tinkoff&Data=%7b%22bot_id%22%3a139%2c%22cloudPayments%22%3a%7b%22recurrent%22%3a%7b%22interval%22%3a%22Month%22%2c%22period%22%3a1%7d%7d%7d&TotalFee=46.76&CardProduct=MNW'
ERROR:django.request:Internal Server Error: /admin/cabinet/payment/6/change/
Traceback (most recent call last):
  File "/usr/local/lib/python3.7/site-packages/django/core/handlers/exception.py", line 34, in inner
    response = get_response(request)
  File "/usr/local/lib/python3.7/site-packages/django/core/handlers/base.py", line 145, in _get_response
    response = self.process_exception_by_middleware(e, request)
  File "/usr/local/lib/python3.7/site-packages/django/core/handlers/base.py", line 143, in _get_response
    response = response.render()
  File "/usr/local/lib/python3.7/site-packages/django/template/response.py", line 106, in render
    self.content = self.rendered_content
  File "/usr/local/lib/python3.7/site-packages/django/template/response.py", line 83, in rendered_content
    content = template.render(context, self._request)
  File "/usr/local/lib/python3.7/site-packages/django/template/backends/django.py", line 61, in render
    return self.template.render(context)
  File "/usr/local/lib/python3.7/site-packages/django/template/base.py", line 171, in render
    return self._render(context)
  File "/usr/local/lib/python3.7/site-packages/django/template/base.py", line 163, in _render
    return self.nodelist.render(context)
  File "/usr/local/lib/python3.7/site-packages/django/template/base.py", line 937, in render
    bit = node.render_annotated(context)
  File "/usr/local/lib/python3.7/site-packages/django/template/base.py", line 904, in render_annotated
    return self.render(context)
  File "/usr/local/lib/python3.7/site-packages/django/template/loader_tags.py", line 150, in render
    return compiled_parent._render(context)
  File "/usr/local/lib/python3.7/site-packages/django/template/base.py", line 163, in _render
    return self.nodelist.render(context)
  File "/usr/local/lib/python3.7/site-packages/django/template/base.py", line 937, in render
    bit = node.render_annotated(context)
  File "/usr/local/lib/python3.7/site-packages/django/template/base.py", line 904, in render_annotated
    return self.render(context)
  File "/usr/local/lib/python3.7/site-packages/django/template/loader_tags.py", line 150, in render
    return compiled_parent._render(context)
  File "/usr/local/lib/python3.7/site-packages/django/template/base.py", line 163, in _render
    return self.nodelist.render(context)
  File "/usr/local/lib/python3.7/site-packages/django/template/base.py", line 937, in render
    bit = node.render_annotated(context)
  File "/usr/local/lib/python3.7/site-packages/django/template/base.py", line 904, in render_annotated
    return self.render(context)
  File "/usr/local/lib/python3.7/site-packages/django/template/defaulttags.py", line 309, in render
    return nodelist.render(context)
  File "/usr/local/lib/python3.7/site-packages/django/template/base.py", line 937, in render
    bit = node.render_annotated(context)
  File "/usr/local/lib/python3.7/site-packages/django/template/base.py", line 904, in render_annotated
    return self.render(context)
  File "/usr/local/lib/python3.7/site-packages/django/template/loader_tags.py", line 62, in render
    result = block.nodelist.render(context)
  File "/usr/local/lib/python3.7/site-packages/django/template/base.py", line 937, in render
    bit = node.render_annotated(context)
  File "/usr/local/lib/python3.7/site-packages/django/template/base.py", line 904, in render_annotated
    return self.render(context)
  File "/usr/local/lib/python3.7/site-packages/django/template/defaulttags.py", line 309, in render
    return nodelist.render(context)
  File "/usr/local/lib/python3.7/site-packages/django/template/base.py", line 937, in render
    bit = node.render_annotated(context)
  File "/usr/local/lib/python3.7/site-packages/django/template/base.py", line 904, in render_annotated
    return self.render(context)
  File "/usr/local/lib/python3.7/site-packages/django/template/base.py", line 987, in render
    output = self.filter_expression.resolve(context)
  File "/usr/local/lib/python3.7/site-packages/django/template/base.py", line 698, in resolve
    new_obj = func(obj, *arg_vals)
  File "/usr/local/lib/python3.7/site-packages/django/template/defaultfilters.py", line 42, in _dec
    args[0] = str(args[0])
TypeError: __str__ returned non-string (type int)
ERROR:django.request:Internal Server Error: /admin/cabinet/payment/7/change/
Traceback (most recent call last):
  File "/usr/local/lib/python3.7/site-packages/django/core/handlers/exception.py", line 34, in inner
    response = get_response(request)
  File "/usr/local/lib/python3.7/site-packages/django/core/handlers/base.py", line 145, in _get_response
    response = self.process_exception_by_middleware(e, request)
  File "/usr/local/lib/python3.7/site-packages/django/core/handlers/base.py", line 143, in _get_response
    response = response.render()
  File "/usr/local/lib/python3.7/site-packages/django/template/response.py", line 106, in render
    self.content = self.rendered_content
  File "/usr/local/lib/python3.7/site-packages/django/template/response.py", line 83, in rendered_content
    content = template.render(context, self._request)
  File "/usr/local/lib/python3.7/site-packages/django/template/backends/django.py", line 61, in render
    return self.template.render(context)
  File "/usr/local/lib/python3.7/site-packages/django/template/base.py", line 171, in render
    return self._render(context)
  File "/usr/local/lib/python3.7/site-packages/django/template/base.py", line 163, in _render
    return self.nodelist.render(context)
  File "/usr/local/lib/python3.7/site-packages/django/template/base.py", line 937, in render
    bit = node.render_annotated(context)
  File "/usr/local/lib/python3.7/site-packages/django/template/base.py", line 904, in render_annotated
    return self.render(context)
  File "/usr/local/lib/python3.7/site-packages/django/template/loader_tags.py", line 150, in render
    return compiled_parent._render(context)
  File "/usr/local/lib/python3.7/site-packages/django/template/base.py", line 163, in _render
    return self.nodelist.render(context)
  File "/usr/local/lib/python3.7/site-packages/django/template/base.py", line 937, in render
    bit = node.render_annotated(context)
  File "/usr/local/lib/python3.7/site-packages/django/template/base.py", line 904, in render_annotated
    return self.render(context)
  File "/usr/local/lib/python3.7/site-packages/django/template/loader_tags.py", line 150, in render
    return compiled_parent._render(context)
  File "/usr/local/lib/python3.7/site-packages/django/template/base.py", line 163, in _render
    return self.nodelist.render(context)
  File "/usr/local/lib/python3.7/site-packages/django/template/base.py", line 937, in render
    bit = node.render_annotated(context)
  File "/usr/local/lib/python3.7/site-packages/django/template/base.py", line 904, in render_annotated
    return self.render(context)
  File "/usr/local/lib/python3.7/site-packages/django/template/defaulttags.py", line 309, in render
    return nodelist.render(context)
  File "/usr/local/lib/python3.7/site-packages/django/template/base.py", line 937, in render
    bit = node.render_annotated(context)
  File "/usr/local/lib/python3.7/site-packages/django/template/base.py", line 904, in render_annotated
    return self.render(context)
  File "/usr/local/lib/python3.7/site-packages/django/template/loader_tags.py", line 62, in render
    result = block.nodelist.render(context)
  File "/usr/local/lib/python3.7/site-packages/django/template/base.py", line 937, in render
    bit = node.render_annotated(context)
  File "/usr/local/lib/python3.7/site-packages/django/template/base.py", line 904, in render_annotated
    return self.render(context)
  File "/usr/local/lib/python3.7/site-packages/django/template/defaulttags.py", line 309, in render
    return nodelist.render(context)
  File "/usr/local/lib/python3.7/site-packages/django/template/base.py", line 937, in render
    bit = node.render_annotated(context)
  File "/usr/local/lib/python3.7/site-packages/django/template/base.py", line 904, in render_annotated
    return self.render(context)
  File "/usr/local/lib/python3.7/site-packages/django/template/base.py", line 987, in render
    output = self.filter_expression.resolve(context)
  File "/usr/local/lib/python3.7/site-packages/django/template/base.py", line 698, in resolve
    new_obj = func(obj, *arg_vals)
  File "/usr/local/lib/python3.7/site-packages/django/template/defaultfilters.py", line 42, in _dec
    args[0] = str(args[0])
TypeError: __str__ returned non-string (type int)
ERROR:django.request:Internal Server Error: /admin/cabinet/payment/7/change/
Traceback (most recent call last):
  File "/usr/local/lib/python3.7/site-packages/django/core/handlers/exception.py", line 34, in inner
    response = get_response(request)
  File "/usr/local/lib/python3.7/site-packages/django/core/handlers/base.py", line 145, in _get_response
    response = self.process_exception_by_middleware(e, request)
  File "/usr/local/lib/python3.7/site-packages/django/core/handlers/base.py", line 143, in _get_response
    response = response.render()
  File "/usr/local/lib/python3.7/site-packages/django/template/response.py", line 106, in render
    self.content = self.rendered_content
  File "/usr/local/lib/python3.7/site-packages/django/template/response.py", line 83, in rendered_content
    content = template.render(context, self._request)
  File "/usr/local/lib/python3.7/site-packages/django/template/backends/django.py", line 61, in render
    return self.template.render(context)
  File "/usr/local/lib/python3.7/site-packages/django/template/base.py", line 171, in render
    return self._render(context)
  File "/usr/local/lib/python3.7/site-packages/django/template/base.py", line 163, in _render
    return self.nodelist.render(context)
  File "/usr/local/lib/python3.7/site-packages/django/template/base.py", line 937, in render
    bit = node.render_annotated(context)
  File "/usr/local/lib/python3.7/site-packages/django/template/base.py", line 904, in render_annotated
    return self.render(context)
  File "/usr/local/lib/python3.7/site-packages/django/template/loader_tags.py", line 150, in render
    return compiled_parent._render(context)
  File "/usr/local/lib/python3.7/site-packages/django/template/base.py", line 163, in _render
    return self.nodelist.render(context)
  File "/usr/local/lib/python3.7/site-packages/django/template/base.py", line 937, in render
    bit = node.render_annotated(context)
  File "/usr/local/lib/python3.7/site-packages/django/template/base.py", line 904, in render_annotated
    return self.render(context)
  File "/usr/local/lib/python3.7/site-packages/django/template/loader_tags.py", line 150, in render
    return compiled_parent._render(context)
  File "/usr/local/lib/python3.7/site-packages/django/template/base.py", line 163, in _render
    return self.nodelist.render(context)
  File "/usr/local/lib/python3.7/site-packages/django/template/base.py", line 937, in render
    bit = node.render_annotated(context)
  File "/usr/local/lib/python3.7/site-packages/django/template/base.py", line 904, in render_annotated
    return self.render(context)
  File "/usr/local/lib/python3.7/site-packages/django/template/defaulttags.py", line 309, in render
    return nodelist.render(context)
  File "/usr/local/lib/python3.7/site-packages/django/template/base.py", line 937, in render
    bit = node.render_annotated(context)
  File "/usr/local/lib/python3.7/site-packages/django/template/base.py", line 904, in render_annotated
    return self.render(context)
  File "/usr/local/lib/python3.7/site-packages/django/template/loader_tags.py", line 62, in render
    result = block.nodelist.render(context)
  File "/usr/local/lib/python3.7/site-packages/django/template/base.py", line 937, in render
    bit = node.render_annotated(context)
  File "/usr/local/lib/python3.7/site-packages/django/template/base.py", line 904, in render_annotated
    return self.render(context)
  File "/usr/local/lib/python3.7/site-packages/django/template/defaulttags.py", line 309, in render
    return nodelist.render(context)
  File "/usr/local/lib/python3.7/site-packages/django/template/base.py", line 937, in render
    bit = node.render_annotated(context)
  File "/usr/local/lib/python3.7/site-packages/django/template/base.py", line 904, in render_annotated
    return self.render(context)
  File "/usr/local/lib/python3.7/site-packages/django/template/base.py", line 987, in render
    output = self.filter_expression.resolve(context)
  File "/usr/local/lib/python3.7/site-packages/django/template/base.py", line 698, in resolve
    new_obj = func(obj, *arg_vals)
  File "/usr/local/lib/python3.7/site-packages/django/template/defaultfilters.py", line 42, in _dec
    args[0] = str(args[0])
TypeError: __str__ returned non-string (type int)
WARNING:django.request:Unauthorized: /api/token/
WARNING:django.request:Not Found: /admin//config.php
WARNING:django.request:Bad Request: /api/register/
WARNING:django.request:Not Found: /admin//config.php
WARNING:django.request:Forbidden: /api/analytics_data/140/
WARNING:django.request:Forbidden: /api/botusers/140/
WARNING:django.request:Not Found: /admin/assets/js/views/login.js
WARNING:django.request:Not Found: /admin/i18n/readme.txt
WARNING:django.request:Not Found: /admin/config.php
WARNING:django.request:Not Found: /admin/config.php
WARNING:django.request:Not Found: /admin/config.php
WARNING:django.request:Not Found: /admin/events/last/
WARNING:django.request:Not Found: /admin/assets/js/views/login.js
WARNING:django.request:Not Found: /admin/i18n/readme.txt
WARNING:django.request:Not Found: /admin/config.php
WARNING:django.request:Forbidden: /api/analytics_data/141/
WARNING:django.request:Forbidden: /api/botusers/141/
WARNING:django.request:Forbidden: /api/compaign_list/141/
WARNING:django.request:Forbidden: /api/analytics_data/141/
WARNING:django.request:Forbidden: /api/botusers/141/
WARNING:django.request:Forbidden: /api/compaign_list/141/
WARNING:django.request:Forbidden: /api/botusers/141/
WARNING:django.request:Forbidden: /api/botusers/141/
WARNING:django.request:Forbidden: /api/compaign_list/141/
WARNING:django.request:Forbidden: /api/compaign_list/141/
WARNING:django.request:Forbidden: /api/botusers/141/
WARNING:django.request:Forbidden: /api/analytics_data/141/
WARNING:django.request:Not Found: /admin/login.php
WARNING:django.request:Not Found: /admin/assets/js/views/login.js
WARNING:django.request:Not Found: /admin/i18n/readme.txt
WARNING:django.request:Not Found: /admin/config.php
ERROR:root:b'TransactionId=195609090&Amount=1.00&Currency=RUB&PaymentAmount=1.00&PaymentCurrency=RUB&OperationType=Payment&InvoiceId=&AccountId=orlan_mh94%40mail.ru&SubscriptionId=sc_facb0e3d678bcf0b01ba8860069a6&Name=MOMENTUM+R&Email=orlan_mh94%40mail.ru&DateTime=2019-08-29+10%3a03%3a53&IpAddress=192.168.3.27&IpCountry=&IpCity=&IpRegion=&IpDistrict=&IpLatitude=&IpLongitude=&CardFirstSix=533669&CardLastFour=7481&CardType=MasterCard&CardExpDate=08%2f21&Issuer=SBERBANK+OF+RUSSIA&IssuerBankCountry=RU&Description=%d0%95%d0%b6%d0%b5%d0%bc%d0%b5%d1%81%d1%8f%d1%87%d0%bd%d0%b0%d1%8f+%d0%bf%d0%be%d0%b4%d0%bf%d0%b8%d1%81%d0%ba%d0%b0+%d0%bd%d0%b0+%d1%82%d0%b0%d1%80%d0%b8%d1%84+Business+%d0%ba+%d0%b1%d0%be%d1%82%d1%83+TEST(id%3d111)%2c+inbot24.ru&AuthCode=271337&Token=540254574&TestMode=0&Status=Completed&GatewayName=Tinkoff&TotalFee=0.04&CardProduct=MCS'
WARNING:django.request:Unauthorized: /api/token/
WARNING:django.request:Forbidden: /api/botusers/143/
WARNING:django.request:Forbidden: /api/analytics_data/143/
WARNING:django.request:Forbidden: /api/compaign_list/143/
WARNING:django.request:Unauthorized: /api/token/
WARNING:django.request:Unauthorized: /api/token/
WARNING:django.request:Unauthorized: /api/token/
WARNING:django.request:Unauthorized: /api/token/
WARNING:django.request:Forbidden: /api/compaign_list/144/
WARNING:django.request:Forbidden: /api/botusers/144/
WARNING:django.request:Forbidden: /api/analytics_data/144/
WARNING:django.request:Not Found: /api/bot_data/134/
WARNING:django.request:Not Found: /api/bot_data/134/
WARNING:django.request:Not Found: /api/bot_data/14/
ERROR:django.request:Internal Server Error: /admin/
Traceback (most recent call last):
  File "/usr/local/lib/python3.7/site-packages/django_redis/cache.py", line 32, in _decorator
    return method(self, *args, **kwargs)
  File "/usr/local/lib/python3.7/site-packages/django_redis/cache.py", line 67, in set
    return self.client.set(*args, **kwargs)
  File "/usr/local/lib/python3.7/site-packages/django_redis/client/default.py", line 149, in set
    raise ConnectionInterrupted(connection=client, parent=e)
django_redis.exceptions.ConnectionInterrupted: Redis ConnectionError: Error -2 connecting to redis:6379. Name or service not known.

During handling of the above exception, another exception occurred:

Traceback (most recent call last):
  File "/usr/local/lib/python3.7/site-packages/django/core/handlers/exception.py", line 34, in inner
    response = get_response(request)
  File "/usr/local/lib/python3.7/site-packages/django/core/handlers/base.py", line 115, in _get_response
    response = self.process_exception_by_middleware(e, request)
  File "/usr/local/lib/python3.7/site-packages/django/core/handlers/base.py", line 113, in _get_response
    response = wrapped_callback(request, *callback_args, **callback_kwargs)
  File "/usr/local/lib/python3.7/site-packages/django/contrib/admin/sites.py", line 241, in wrapper
    return self.admin_view(view, cacheable)(*args, **kwargs)
  File "/usr/local/lib/python3.7/site-packages/django/utils/decorators.py", line 142, in _wrapped_view
    response = view_func(request, *args, **kwargs)
  File "/usr/local/lib/python3.7/site-packages/django/views/decorators/cache.py", line 44, in _wrapped_view_func
    response = view_func(request, *args, **kwargs)
  File "/usr/local/lib/python3.7/site-packages/django/contrib/admin/sites.py", line 212, in inner
    if not self.has_permission(request):
  File "/usr/local/lib/python3.7/site-packages/django/contrib/admin/sites.py", line 186, in has_permission
    return request.user.is_active and request.user.is_staff
  File "/usr/local/lib/python3.7/site-packages/django/utils/functional.py", line 256, in inner
    self._setup()
  File "/usr/local/lib/python3.7/site-packages/django/utils/functional.py", line 392, in _setup
    self._wrapped = self._setupfunc()
  File "/usr/local/lib/python3.7/site-packages/django/contrib/auth/middleware.py", line 24, in <lambda>
    request.user = SimpleLazyObject(lambda: get_user(request))
  File "/usr/local/lib/python3.7/site-packages/django/contrib/auth/middleware.py", line 12, in get_user
    request._cached_user = auth.get_user(request)
  File "/usr/local/lib/python3.7/site-packages/django/contrib/auth/__init__.py", line 182, in get_user
    user_id = _get_user_session_key(request)
  File "/usr/local/lib/python3.7/site-packages/django/contrib/auth/__init__.py", line 59, in _get_user_session_key
    return get_user_model()._meta.pk.to_python(request.session[SESSION_KEY])
  File "/usr/local/lib/python3.7/site-packages/django/contrib/sessions/backends/base.py", line 54, in __getitem__
    return self._session[key]
  File "/usr/local/lib/python3.7/site-packages/django/contrib/sessions/backends/base.py", line 194, in _get_session
    self._session_cache = self.load()
  File "/usr/local/lib/python3.7/site-packages/django/contrib/sessions/backends/cached_db.py", line 38, in load
    self._cache.set(self.cache_key, data, self.get_expiry_age(expiry=s.expire_date))
  File "/usr/local/lib/python3.7/site-packages/django_redis/cache.py", line 39, in _decorator
    raise e.parent
  File "/usr/local/lib/python3.7/site-packages/django_redis/client/default.py", line 143, in set
    return client.set(nkey, nvalue, nx=nx, px=timeout, xx=xx)
  File "/usr/local/lib/python3.7/site-packages/redis/client.py", line 1451, in set
    return self.execute_command('SET', *pieces)
  File "/usr/local/lib/python3.7/site-packages/redis/client.py", line 772, in execute_command
    connection = pool.get_connection(command_name, **options)
  File "/usr/local/lib/python3.7/site-packages/redis/connection.py", line 994, in get_connection
    connection.connect()
  File "/usr/local/lib/python3.7/site-packages/redis/connection.py", line 497, in connect
    raise ConnectionError(self._error_message(e))
redis.exceptions.ConnectionError: Error -2 connecting to redis:6379. Name or service not known.
ERROR:django.request:Internal Server Error: /admin/
Traceback (most recent call last):
  File "/usr/local/lib/python3.7/site-packages/django_redis/cache.py", line 32, in _decorator
    return method(self, *args, **kwargs)
  File "/usr/local/lib/python3.7/site-packages/django_redis/cache.py", line 67, in set
    return self.client.set(*args, **kwargs)
  File "/usr/local/lib/python3.7/site-packages/django_redis/client/default.py", line 149, in set
    raise ConnectionInterrupted(connection=client, parent=e)
django_redis.exceptions.ConnectionInterrupted: Redis ConnectionError: Error -2 connecting to redis:6379. Name or service not known.

During handling of the above exception, another exception occurred:

Traceback (most recent call last):
  File "/usr/local/lib/python3.7/site-packages/django/core/handlers/exception.py", line 34, in inner
    response = get_response(request)
  File "/usr/local/lib/python3.7/site-packages/django/core/handlers/base.py", line 115, in _get_response
    response = self.process_exception_by_middleware(e, request)
  File "/usr/local/lib/python3.7/site-packages/django/core/handlers/base.py", line 113, in _get_response
    response = wrapped_callback(request, *callback_args, **callback_kwargs)
  File "/usr/local/lib/python3.7/site-packages/django/contrib/admin/sites.py", line 241, in wrapper
    return self.admin_view(view, cacheable)(*args, **kwargs)
  File "/usr/local/lib/python3.7/site-packages/django/utils/decorators.py", line 142, in _wrapped_view
    response = view_func(request, *args, **kwargs)
  File "/usr/local/lib/python3.7/site-packages/django/views/decorators/cache.py", line 44, in _wrapped_view_func
    response = view_func(request, *args, **kwargs)
  File "/usr/local/lib/python3.7/site-packages/django/contrib/admin/sites.py", line 212, in inner
    if not self.has_permission(request):
  File "/usr/local/lib/python3.7/site-packages/django/contrib/admin/sites.py", line 186, in has_permission
    return request.user.is_active and request.user.is_staff
  File "/usr/local/lib/python3.7/site-packages/django/utils/functional.py", line 256, in inner
    self._setup()
  File "/usr/local/lib/python3.7/site-packages/django/utils/functional.py", line 392, in _setup
    self._wrapped = self._setupfunc()
  File "/usr/local/lib/python3.7/site-packages/django/contrib/auth/middleware.py", line 24, in <lambda>
    request.user = SimpleLazyObject(lambda: get_user(request))
  File "/usr/local/lib/python3.7/site-packages/django/contrib/auth/middleware.py", line 12, in get_user
    request._cached_user = auth.get_user(request)
  File "/usr/local/lib/python3.7/site-packages/django/contrib/auth/__init__.py", line 182, in get_user
    user_id = _get_user_session_key(request)
  File "/usr/local/lib/python3.7/site-packages/django/contrib/auth/__init__.py", line 59, in _get_user_session_key
    return get_user_model()._meta.pk.to_python(request.session[SESSION_KEY])
  File "/usr/local/lib/python3.7/site-packages/django/contrib/sessions/backends/base.py", line 54, in __getitem__
    return self._session[key]
  File "/usr/local/lib/python3.7/site-packages/django/contrib/sessions/backends/base.py", line 194, in _get_session
    self._session_cache = self.load()
  File "/usr/local/lib/python3.7/site-packages/django/contrib/sessions/backends/cached_db.py", line 38, in load
    self._cache.set(self.cache_key, data, self.get_expiry_age(expiry=s.expire_date))
  File "/usr/local/lib/python3.7/site-packages/django_redis/cache.py", line 39, in _decorator
    raise e.parent
  File "/usr/local/lib/python3.7/site-packages/django_redis/client/default.py", line 143, in set
    return client.set(nkey, nvalue, nx=nx, px=timeout, xx=xx)
  File "/usr/local/lib/python3.7/site-packages/redis/client.py", line 1451, in set
    return self.execute_command('SET', *pieces)
  File "/usr/local/lib/python3.7/site-packages/redis/client.py", line 772, in execute_command
    connection = pool.get_connection(command_name, **options)
  File "/usr/local/lib/python3.7/site-packages/redis/connection.py", line 994, in get_connection
    connection.connect()
  File "/usr/local/lib/python3.7/site-packages/redis/connection.py", line 497, in connect
    raise ConnectionError(self._error_message(e))
redis.exceptions.ConnectionError: Error -2 connecting to redis:6379. Name or service not known.
ERROR:django.request:Internal Server Error: /admin/
Traceback (most recent call last):
  File "/usr/local/lib/python3.7/site-packages/django_redis/cache.py", line 32, in _decorator
    return method(self, *args, **kwargs)
  File "/usr/local/lib/python3.7/site-packages/django_redis/cache.py", line 67, in set
    return self.client.set(*args, **kwargs)
  File "/usr/local/lib/python3.7/site-packages/django_redis/client/default.py", line 149, in set
    raise ConnectionInterrupted(connection=client, parent=e)
django_redis.exceptions.ConnectionInterrupted: Redis ConnectionError: Error -2 connecting to redis:6379. Name or service not known.

During handling of the above exception, another exception occurred:

Traceback (most recent call last):
  File "/usr/local/lib/python3.7/site-packages/django/core/handlers/exception.py", line 34, in inner
    response = get_response(request)
  File "/usr/local/lib/python3.7/site-packages/django/core/handlers/base.py", line 115, in _get_response
    response = self.process_exception_by_middleware(e, request)
  File "/usr/local/lib/python3.7/site-packages/django/core/handlers/base.py", line 113, in _get_response
    response = wrapped_callback(request, *callback_args, **callback_kwargs)
  File "/usr/local/lib/python3.7/site-packages/django/contrib/admin/sites.py", line 241, in wrapper
    return self.admin_view(view, cacheable)(*args, **kwargs)
  File "/usr/local/lib/python3.7/site-packages/django/utils/decorators.py", line 142, in _wrapped_view
    response = view_func(request, *args, **kwargs)
  File "/usr/local/lib/python3.7/site-packages/django/views/decorators/cache.py", line 44, in _wrapped_view_func
    response = view_func(request, *args, **kwargs)
  File "/usr/local/lib/python3.7/site-packages/django/contrib/admin/sites.py", line 212, in inner
    if not self.has_permission(request):
  File "/usr/local/lib/python3.7/site-packages/django/contrib/admin/sites.py", line 186, in has_permission
    return request.user.is_active and request.user.is_staff
  File "/usr/local/lib/python3.7/site-packages/django/utils/functional.py", line 256, in inner
    self._setup()
  File "/usr/local/lib/python3.7/site-packages/django/utils/functional.py", line 392, in _setup
    self._wrapped = self._setupfunc()
  File "/usr/local/lib/python3.7/site-packages/django/contrib/auth/middleware.py", line 24, in <lambda>
    request.user = SimpleLazyObject(lambda: get_user(request))
  File "/usr/local/lib/python3.7/site-packages/django/contrib/auth/middleware.py", line 12, in get_user
    request._cached_user = auth.get_user(request)
  File "/usr/local/lib/python3.7/site-packages/django/contrib/auth/__init__.py", line 182, in get_user
    user_id = _get_user_session_key(request)
  File "/usr/local/lib/python3.7/site-packages/django/contrib/auth/__init__.py", line 59, in _get_user_session_key
    return get_user_model()._meta.pk.to_python(request.session[SESSION_KEY])
  File "/usr/local/lib/python3.7/site-packages/django/contrib/sessions/backends/base.py", line 54, in __getitem__
    return self._session[key]
  File "/usr/local/lib/python3.7/site-packages/django/contrib/sessions/backends/base.py", line 194, in _get_session
    self._session_cache = self.load()
  File "/usr/local/lib/python3.7/site-packages/django/contrib/sessions/backends/cached_db.py", line 38, in load
    self._cache.set(self.cache_key, data, self.get_expiry_age(expiry=s.expire_date))
  File "/usr/local/lib/python3.7/site-packages/django_redis/cache.py", line 39, in _decorator
    raise e.parent
  File "/usr/local/lib/python3.7/site-packages/django_redis/client/default.py", line 143, in set
    return client.set(nkey, nvalue, nx=nx, px=timeout, xx=xx)
  File "/usr/local/lib/python3.7/site-packages/redis/client.py", line 1451, in set
    return self.execute_command('SET', *pieces)
  File "/usr/local/lib/python3.7/site-packages/redis/client.py", line 772, in execute_command
    connection = pool.get_connection(command_name, **options)
  File "/usr/local/lib/python3.7/site-packages/redis/connection.py", line 994, in get_connection
    connection.connect()
  File "/usr/local/lib/python3.7/site-packages/redis/connection.py", line 497, in connect
    raise ConnectionError(self._error_message(e))
redis.exceptions.ConnectionError: Error -2 connecting to redis:6379. Name or service not known.
ERROR:root:b'TransactionId=199773737&Amount=1.00&Currency=RUB&PaymentAmount=1.00&PaymentCurrency=RUB&OperationType=Payment&InvoiceId=&AccountId=nurarip%40yandex.ru&SubscriptionId=sc_1422987a13cc6d89c5ac709ea974a&Name=ARIP+NURMAGOMEDOV&Email=nurarip%40yandex.ru&DateTime=2019-09-06+10%3a58%3a57&IpAddress=192.168.3.27&IpCountry=&IpCity=&IpRegion=&IpDistrict=&IpLatitude=&IpLongitude=&CardFirstSix=521324&CardLastFour=0913&CardType=MasterCard&CardExpDate=04%2f21&Issuer=TINKOFF+BANK&IssuerBankCountry=RU&Description=%d0%95%d0%b6%d0%b5%d0%bc%d0%b5%d1%81%d1%8f%d1%87%d0%bd%d0%b0%d1%8f+%d0%bf%d0%be%d0%b4%d0%bf%d0%b8%d1%81%d0%ba%d0%b0+%d0%bd%d0%b0+%d1%82%d0%b0%d1%80%d0%b8%d1%84+Business+%d0%ba+%d0%b1%d0%be%d1%82%d1%83+Test(id%3d116)%2c+inbot24.ru&AuthCode=082726&Token=543011578&TestMode=0&Status=Completed&GatewayName=Tinkoff&TotalFee=0.04&CardProduct=MNW'
ERROR:django.request:Internal Server Error: /admin/
Traceback (most recent call last):
  File "/usr/local/lib/python3.7/site-packages/django_redis/cache.py", line 32, in _decorator
    return method(self, *args, **kwargs)
  File "/usr/local/lib/python3.7/site-packages/django_redis/cache.py", line 67, in set
    return self.client.set(*args, **kwargs)
  File "/usr/local/lib/python3.7/site-packages/django_redis/client/default.py", line 149, in set
    raise ConnectionInterrupted(connection=client, parent=e)
django_redis.exceptions.ConnectionInterrupted: Redis ConnectionError: Error -2 connecting to redis:6379. Name or service not known.

During handling of the above exception, another exception occurred:

Traceback (most recent call last):
  File "/usr/local/lib/python3.7/site-packages/django/core/handlers/exception.py", line 34, in inner
    response = get_response(request)
  File "/usr/local/lib/python3.7/site-packages/django/core/handlers/base.py", line 115, in _get_response
    response = self.process_exception_by_middleware(e, request)
  File "/usr/local/lib/python3.7/site-packages/django/core/handlers/base.py", line 113, in _get_response
    response = wrapped_callback(request, *callback_args, **callback_kwargs)
  File "/usr/local/lib/python3.7/site-packages/django/contrib/admin/sites.py", line 241, in wrapper
    return self.admin_view(view, cacheable)(*args, **kwargs)
  File "/usr/local/lib/python3.7/site-packages/django/utils/decorators.py", line 142, in _wrapped_view
    response = view_func(request, *args, **kwargs)
  File "/usr/local/lib/python3.7/site-packages/django/views/decorators/cache.py", line 44, in _wrapped_view_func
    response = view_func(request, *args, **kwargs)
  File "/usr/local/lib/python3.7/site-packages/django/contrib/admin/sites.py", line 212, in inner
    if not self.has_permission(request):
  File "/usr/local/lib/python3.7/site-packages/django/contrib/admin/sites.py", line 186, in has_permission
    return request.user.is_active and request.user.is_staff
  File "/usr/local/lib/python3.7/site-packages/django/utils/functional.py", line 256, in inner
    self._setup()
  File "/usr/local/lib/python3.7/site-packages/django/utils/functional.py", line 392, in _setup
    self._wrapped = self._setupfunc()
  File "/usr/local/lib/python3.7/site-packages/django/contrib/auth/middleware.py", line 24, in <lambda>
    request.user = SimpleLazyObject(lambda: get_user(request))
  File "/usr/local/lib/python3.7/site-packages/django/contrib/auth/middleware.py", line 12, in get_user
    request._cached_user = auth.get_user(request)
  File "/usr/local/lib/python3.7/site-packages/django/contrib/auth/__init__.py", line 182, in get_user
    user_id = _get_user_session_key(request)
  File "/usr/local/lib/python3.7/site-packages/django/contrib/auth/__init__.py", line 59, in _get_user_session_key
    return get_user_model()._meta.pk.to_python(request.session[SESSION_KEY])
  File "/usr/local/lib/python3.7/site-packages/django/contrib/sessions/backends/base.py", line 54, in __getitem__
    return self._session[key]
  File "/usr/local/lib/python3.7/site-packages/django/contrib/sessions/backends/base.py", line 194, in _get_session
    self._session_cache = self.load()
  File "/usr/local/lib/python3.7/site-packages/django/contrib/sessions/backends/cached_db.py", line 38, in load
    self._cache.set(self.cache_key, data, self.get_expiry_age(expiry=s.expire_date))
  File "/usr/local/lib/python3.7/site-packages/django_redis/cache.py", line 39, in _decorator
    raise e.parent
  File "/usr/local/lib/python3.7/site-packages/django_redis/client/default.py", line 143, in set
    return client.set(nkey, nvalue, nx=nx, px=timeout, xx=xx)
  File "/usr/local/lib/python3.7/site-packages/redis/client.py", line 1451, in set
    return self.execute_command('SET', *pieces)
  File "/usr/local/lib/python3.7/site-packages/redis/client.py", line 772, in execute_command
    connection = pool.get_connection(command_name, **options)
  File "/usr/local/lib/python3.7/site-packages/redis/connection.py", line 994, in get_connection
    connection.connect()
  File "/usr/local/lib/python3.7/site-packages/redis/connection.py", line 497, in connect
    raise ConnectionError(self._error_message(e))
redis.exceptions.ConnectionError: Error -2 connecting to redis:6379. Name or service not known.
WARNING:django.request:Forbidden: /api/compaign_list/144/
WARNING:django.request:Forbidden: /api/compaign_list/144/
WARNING:django.request:Bad Request: /api/set_webhook/144/
WARNING:django.request:Bad Request: /api/set_webhook/144/
ERROR:django.request:Internal Server Error: /admin/
Traceback (most recent call last):
  File "/usr/local/lib/python3.7/site-packages/django_redis/cache.py", line 32, in _decorator
    return method(self, *args, **kwargs)
  File "/usr/local/lib/python3.7/site-packages/django_redis/cache.py", line 67, in set
    return self.client.set(*args, **kwargs)
  File "/usr/local/lib/python3.7/site-packages/django_redis/client/default.py", line 149, in set
    raise ConnectionInterrupted(connection=client, parent=e)
django_redis.exceptions.ConnectionInterrupted: Redis ConnectionError: Error -2 connecting to redis:6379. Name or service not known.

During handling of the above exception, another exception occurred:

Traceback (most recent call last):
  File "/usr/local/lib/python3.7/site-packages/django/core/handlers/exception.py", line 34, in inner
    response = get_response(request)
  File "/usr/local/lib/python3.7/site-packages/django/core/handlers/base.py", line 115, in _get_response
    response = self.process_exception_by_middleware(e, request)
  File "/usr/local/lib/python3.7/site-packages/django/core/handlers/base.py", line 113, in _get_response
    response = wrapped_callback(request, *callback_args, **callback_kwargs)
  File "/usr/local/lib/python3.7/site-packages/django/contrib/admin/sites.py", line 241, in wrapper
    return self.admin_view(view, cacheable)(*args, **kwargs)
  File "/usr/local/lib/python3.7/site-packages/django/utils/decorators.py", line 142, in _wrapped_view
    response = view_func(request, *args, **kwargs)
  File "/usr/local/lib/python3.7/site-packages/django/views/decorators/cache.py", line 44, in _wrapped_view_func
    response = view_func(request, *args, **kwargs)
  File "/usr/local/lib/python3.7/site-packages/django/contrib/admin/sites.py", line 212, in inner
    if not self.has_permission(request):
  File "/usr/local/lib/python3.7/site-packages/django/contrib/admin/sites.py", line 186, in has_permission
    return request.user.is_active and request.user.is_staff
  File "/usr/local/lib/python3.7/site-packages/django/utils/functional.py", line 256, in inner
    self._setup()
  File "/usr/local/lib/python3.7/site-packages/django/utils/functional.py", line 392, in _setup
    self._wrapped = self._setupfunc()
  File "/usr/local/lib/python3.7/site-packages/django/contrib/auth/middleware.py", line 24, in <lambda>
    request.user = SimpleLazyObject(lambda: get_user(request))
  File "/usr/local/lib/python3.7/site-packages/django/contrib/auth/middleware.py", line 12, in get_user
    request._cached_user = auth.get_user(request)
  File "/usr/local/lib/python3.7/site-packages/django/contrib/auth/__init__.py", line 182, in get_user
    user_id = _get_user_session_key(request)
  File "/usr/local/lib/python3.7/site-packages/django/contrib/auth/__init__.py", line 59, in _get_user_session_key
    return get_user_model()._meta.pk.to_python(request.session[SESSION_KEY])
  File "/usr/local/lib/python3.7/site-packages/django/contrib/sessions/backends/base.py", line 54, in __getitem__
    return self._session[key]
  File "/usr/local/lib/python3.7/site-packages/django/contrib/sessions/backends/base.py", line 194, in _get_session
    self._session_cache = self.load()
  File "/usr/local/lib/python3.7/site-packages/django/contrib/sessions/backends/cached_db.py", line 38, in load
    self._cache.set(self.cache_key, data, self.get_expiry_age(expiry=s.expire_date))
  File "/usr/local/lib/python3.7/site-packages/django_redis/cache.py", line 39, in _decorator
    raise e.parent
  File "/usr/local/lib/python3.7/site-packages/django_redis/client/default.py", line 143, in set
    return client.set(nkey, nvalue, nx=nx, px=timeout, xx=xx)
  File "/usr/local/lib/python3.7/site-packages/redis/client.py", line 1451, in set
    return self.execute_command('SET', *pieces)
  File "/usr/local/lib/python3.7/site-packages/redis/client.py", line 772, in execute_command
    connection = pool.get_connection(command_name, **options)
  File "/usr/local/lib/python3.7/site-packages/redis/connection.py", line 994, in get_connection
    connection.connect()
  File "/usr/local/lib/python3.7/site-packages/redis/connection.py", line 497, in connect
    raise ConnectionError(self._error_message(e))
redis.exceptions.ConnectionError: Error -2 connecting to redis:6379. Name or service not known.
ERROR:django.request:Internal Server Error: /admin/
Traceback (most recent call last):
  File "/usr/local/lib/python3.7/site-packages/django_redis/cache.py", line 32, in _decorator
    return method(self, *args, **kwargs)
  File "/usr/local/lib/python3.7/site-packages/django_redis/cache.py", line 67, in set
    return self.client.set(*args, **kwargs)
  File "/usr/local/lib/python3.7/site-packages/django_redis/client/default.py", line 149, in set
    raise ConnectionInterrupted(connection=client, parent=e)
django_redis.exceptions.ConnectionInterrupted: Redis ConnectionError: Error -2 connecting to redis:6379. Name or service not known.

During handling of the above exception, another exception occurred:

Traceback (most recent call last):
  File "/usr/local/lib/python3.7/site-packages/django/core/handlers/exception.py", line 34, in inner
    response = get_response(request)
  File "/usr/local/lib/python3.7/site-packages/django/core/handlers/base.py", line 115, in _get_response
    response = self.process_exception_by_middleware(e, request)
  File "/usr/local/lib/python3.7/site-packages/django/core/handlers/base.py", line 113, in _get_response
    response = wrapped_callback(request, *callback_args, **callback_kwargs)
  File "/usr/local/lib/python3.7/site-packages/django/contrib/admin/sites.py", line 241, in wrapper
    return self.admin_view(view, cacheable)(*args, **kwargs)
  File "/usr/local/lib/python3.7/site-packages/django/utils/decorators.py", line 142, in _wrapped_view
    response = view_func(request, *args, **kwargs)
  File "/usr/local/lib/python3.7/site-packages/django/views/decorators/cache.py", line 44, in _wrapped_view_func
    response = view_func(request, *args, **kwargs)
  File "/usr/local/lib/python3.7/site-packages/django/contrib/admin/sites.py", line 212, in inner
    if not self.has_permission(request):
  File "/usr/local/lib/python3.7/site-packages/django/contrib/admin/sites.py", line 186, in has_permission
    return request.user.is_active and request.user.is_staff
  File "/usr/local/lib/python3.7/site-packages/django/utils/functional.py", line 256, in inner
    self._setup()
  File "/usr/local/lib/python3.7/site-packages/django/utils/functional.py", line 392, in _setup
    self._wrapped = self._setupfunc()
  File "/usr/local/lib/python3.7/site-packages/django/contrib/auth/middleware.py", line 24, in <lambda>
    request.user = SimpleLazyObject(lambda: get_user(request))
  File "/usr/local/lib/python3.7/site-packages/django/contrib/auth/middleware.py", line 12, in get_user
    request._cached_user = auth.get_user(request)
  File "/usr/local/lib/python3.7/site-packages/django/contrib/auth/__init__.py", line 182, in get_user
    user_id = _get_user_session_key(request)
  File "/usr/local/lib/python3.7/site-packages/django/contrib/auth/__init__.py", line 59, in _get_user_session_key
    return get_user_model()._meta.pk.to_python(request.session[SESSION_KEY])
  File "/usr/local/lib/python3.7/site-packages/django/contrib/sessions/backends/base.py", line 54, in __getitem__
    return self._session[key]
  File "/usr/local/lib/python3.7/site-packages/django/contrib/sessions/backends/base.py", line 194, in _get_session
    self._session_cache = self.load()
  File "/usr/local/lib/python3.7/site-packages/django/contrib/sessions/backends/cached_db.py", line 38, in load
    self._cache.set(self.cache_key, data, self.get_expiry_age(expiry=s.expire_date))
  File "/usr/local/lib/python3.7/site-packages/django_redis/cache.py", line 39, in _decorator
    raise e.parent
  File "/usr/local/lib/python3.7/site-packages/django_redis/client/default.py", line 143, in set
    return client.set(nkey, nvalue, nx=nx, px=timeout, xx=xx)
  File "/usr/local/lib/python3.7/site-packages/redis/client.py", line 1451, in set
    return self.execute_command('SET', *pieces)
  File "/usr/local/lib/python3.7/site-packages/redis/client.py", line 772, in execute_command
    connection = pool.get_connection(command_name, **options)
  File "/usr/local/lib/python3.7/site-packages/redis/connection.py", line 994, in get_connection
    connection.connect()
  File "/usr/local/lib/python3.7/site-packages/redis/connection.py", line 497, in connect
    raise ConnectionError(self._error_message(e))
redis.exceptions.ConnectionError: Error -2 connecting to redis:6379. Name or service not known.
WARNING:django.request:Not Found: /admin.php
WARNING:django.request:Forbidden: /api/compaign_list/120/
WARNING:django.request:Forbidden: /api/botusers/120/
WARNING:django.request:Forbidden: /api/analytics_data/120/
WARNING:django.request:Forbidden: /api/botusers/120/
WARNING:django.request:Forbidden: /api/analytics_data/120/
ERROR:django.request:Internal Server Error: /admin/
Traceback (most recent call last):
  File "/usr/local/lib/python3.7/site-packages/django_redis/cache.py", line 32, in _decorator
    return method(self, *args, **kwargs)
  File "/usr/local/lib/python3.7/site-packages/django_redis/cache.py", line 67, in set
    return self.client.set(*args, **kwargs)
  File "/usr/local/lib/python3.7/site-packages/django_redis/client/default.py", line 149, in set
    raise ConnectionInterrupted(connection=client, parent=e)
django_redis.exceptions.ConnectionInterrupted: Redis ConnectionError: Error -2 connecting to redis:6379. Name or service not known.

During handling of the above exception, another exception occurred:

Traceback (most recent call last):
  File "/usr/local/lib/python3.7/site-packages/django/core/handlers/exception.py", line 34, in inner
    response = get_response(request)
  File "/usr/local/lib/python3.7/site-packages/django/core/handlers/base.py", line 115, in _get_response
    response = self.process_exception_by_middleware(e, request)
  File "/usr/local/lib/python3.7/site-packages/django/core/handlers/base.py", line 113, in _get_response
    response = wrapped_callback(request, *callback_args, **callback_kwargs)
  File "/usr/local/lib/python3.7/site-packages/django/contrib/admin/sites.py", line 241, in wrapper
    return self.admin_view(view, cacheable)(*args, **kwargs)
  File "/usr/local/lib/python3.7/site-packages/django/utils/decorators.py", line 142, in _wrapped_view
    response = view_func(request, *args, **kwargs)
  File "/usr/local/lib/python3.7/site-packages/django/views/decorators/cache.py", line 44, in _wrapped_view_func
    response = view_func(request, *args, **kwargs)
  File "/usr/local/lib/python3.7/site-packages/django/contrib/admin/sites.py", line 212, in inner
    if not self.has_permission(request):
  File "/usr/local/lib/python3.7/site-packages/django/contrib/admin/sites.py", line 186, in has_permission
    return request.user.is_active and request.user.is_staff
  File "/usr/local/lib/python3.7/site-packages/django/utils/functional.py", line 256, in inner
    self._setup()
  File "/usr/local/lib/python3.7/site-packages/django/utils/functional.py", line 392, in _setup
    self._wrapped = self._setupfunc()
  File "/usr/local/lib/python3.7/site-packages/django/contrib/auth/middleware.py", line 24, in <lambda>
    request.user = SimpleLazyObject(lambda: get_user(request))
  File "/usr/local/lib/python3.7/site-packages/django/contrib/auth/middleware.py", line 12, in get_user
    request._cached_user = auth.get_user(request)
  File "/usr/local/lib/python3.7/site-packages/django/contrib/auth/__init__.py", line 182, in get_user
    user_id = _get_user_session_key(request)
  File "/usr/local/lib/python3.7/site-packages/django/contrib/auth/__init__.py", line 59, in _get_user_session_key
    return get_user_model()._meta.pk.to_python(request.session[SESSION_KEY])
  File "/usr/local/lib/python3.7/site-packages/django/contrib/sessions/backends/base.py", line 54, in __getitem__
    return self._session[key]
  File "/usr/local/lib/python3.7/site-packages/django/contrib/sessions/backends/base.py", line 194, in _get_session
    self._session_cache = self.load()
  File "/usr/local/lib/python3.7/site-packages/django/contrib/sessions/backends/cached_db.py", line 38, in load
    self._cache.set(self.cache_key, data, self.get_expiry_age(expiry=s.expire_date))
  File "/usr/local/lib/python3.7/site-packages/django_redis/cache.py", line 39, in _decorator
    raise e.parent
  File "/usr/local/lib/python3.7/site-packages/django_redis/client/default.py", line 143, in set
    return client.set(nkey, nvalue, nx=nx, px=timeout, xx=xx)
  File "/usr/local/lib/python3.7/site-packages/redis/client.py", line 1451, in set
    return self.execute_command('SET', *pieces)
  File "/usr/local/lib/python3.7/site-packages/redis/client.py", line 772, in execute_command
    connection = pool.get_connection(command_name, **options)
  File "/usr/local/lib/python3.7/site-packages/redis/connection.py", line 994, in get_connection
    connection.connect()
  File "/usr/local/lib/python3.7/site-packages/redis/connection.py", line 497, in connect
    raise ConnectionError(self._error_message(e))
redis.exceptions.ConnectionError: Error -2 connecting to redis:6379. Name or service not known.
WARNING:django.request:Unauthorized: /api/token/
WARNING:django.request:Unauthorized: /api/token/
WARNING:django.request:Forbidden: /api/analytics_data/119/
WARNING:django.request:Forbidden: /api/botusers/119/
WARNING:django.request:Forbidden: /api/compaign_list/119/
ERROR:django.request:Internal Server Error: /admin/login/
Traceback (most recent call last):
  File "/usr/local/lib/python3.7/site-packages/django_redis/cache.py", line 32, in _decorator
    return method(self, *args, **kwargs)
  File "/usr/local/lib/python3.7/site-packages/django_redis/cache.py", line 124, in has_key
    return self.client.has_key(*args, **kwargs)
  File "/usr/local/lib/python3.7/site-packages/django_redis/client/default.py", line 478, in has_key
    raise ConnectionInterrupted(connection=client, parent=e)
django_redis.exceptions.ConnectionInterrupted: Redis ConnectionError: Error -2 connecting to redis:6379. Name or service not known.

During handling of the above exception, another exception occurred:

Traceback (most recent call last):
  File "/usr/local/lib/python3.7/site-packages/django/core/handlers/exception.py", line 34, in inner
    response = get_response(request)
  File "/usr/local/lib/python3.7/site-packages/django/core/handlers/base.py", line 115, in _get_response
    response = self.process_exception_by_middleware(e, request)
  File "/usr/local/lib/python3.7/site-packages/django/core/handlers/base.py", line 113, in _get_response
    response = wrapped_callback(request, *callback_args, **callback_kwargs)
  File "/usr/local/lib/python3.7/site-packages/django/views/decorators/cache.py", line 44, in _wrapped_view_func
    response = view_func(request, *args, **kwargs)
  File "/usr/local/lib/python3.7/site-packages/django/contrib/admin/sites.py", line 399, in login
    return LoginView.as_view(**defaults)(request)
  File "/usr/local/lib/python3.7/site-packages/django/views/generic/base.py", line 71, in view
    return self.dispatch(request, *args, **kwargs)
  File "/usr/local/lib/python3.7/site-packages/django/utils/decorators.py", line 45, in _wrapper
    return bound_method(*args, **kwargs)
  File "/usr/local/lib/python3.7/site-packages/django/views/decorators/debug.py", line 76, in sensitive_post_parameters_wrapper
    return view(request, *args, **kwargs)
  File "/usr/local/lib/python3.7/site-packages/django/utils/decorators.py", line 45, in _wrapper
    return bound_method(*args, **kwargs)
  File "/usr/local/lib/python3.7/site-packages/django/utils/decorators.py", line 142, in _wrapped_view
    response = view_func(request, *args, **kwargs)
  File "/usr/local/lib/python3.7/site-packages/django/utils/decorators.py", line 45, in _wrapper
    return bound_method(*args, **kwargs)
  File "/usr/local/lib/python3.7/site-packages/django/views/decorators/cache.py", line 44, in _wrapped_view_func
    response = view_func(request, *args, **kwargs)
  File "/usr/local/lib/python3.7/site-packages/django/contrib/auth/views.py", line 61, in dispatch
    return super().dispatch(request, *args, **kwargs)
  File "/usr/local/lib/python3.7/site-packages/django/views/generic/base.py", line 97, in dispatch
    return handler(request, *args, **kwargs)
  File "/usr/local/lib/python3.7/site-packages/django/views/generic/edit.py", line 142, in post
    return self.form_valid(form)
  File "/usr/local/lib/python3.7/site-packages/django/contrib/auth/views.py", line 90, in form_valid
    auth_login(self.request, form.get_user())
  File "/usr/local/lib/python3.7/site-packages/django/contrib/auth/__init__.py", line 108, in login
    request.session.cycle_key()
  File "/usr/local/lib/python3.7/site-packages/django/contrib/sessions/backends/base.py", line 297, in cycle_key
    self.create()
  File "/usr/local/lib/python3.7/site-packages/django/contrib/sessions/backends/db.py", line 51, in create
    self._session_key = self._get_new_session_key()
  File "/usr/local/lib/python3.7/site-packages/django/contrib/sessions/backends/base.py", line 152, in _get_new_session_key
    if not self.exists(session_key):
  File "/usr/local/lib/python3.7/site-packages/django/contrib/sessions/backends/cached_db.py", line 44, in exists
    return session_key and (self.cache_key_prefix + session_key) in self._cache or super().exists(session_key)
  File "/usr/local/lib/python3.7/site-packages/django/core/cache/backends/base.py", line 208, in __contains__
    return self.has_key(key)
  File "/usr/local/lib/python3.7/site-packages/django_redis/cache.py", line 39, in _decorator
    raise e.parent
  File "/usr/local/lib/python3.7/site-packages/django_redis/client/default.py", line 476, in has_key
    return client.exists(key) == 1
  File "/usr/local/lib/python3.7/site-packages/redis/client.py", line 1239, in exists
    return self.execute_command('EXISTS', *names)
  File "/usr/local/lib/python3.7/site-packages/redis/client.py", line 772, in execute_command
    connection = pool.get_connection(command_name, **options)
  File "/usr/local/lib/python3.7/site-packages/redis/connection.py", line 994, in get_connection
    connection.connect()
  File "/usr/local/lib/python3.7/site-packages/redis/connection.py", line 497, in connect
    raise ConnectionError(self._error_message(e))
redis.exceptions.ConnectionError: Error -2 connecting to redis:6379. Name or service not known.
ERROR:root:b'TransactionId=204122621&Amount=1.00&Currency=RUB&PaymentAmount=1.00&PaymentCurrency=RUB&OperationType=Payment&InvoiceId=&AccountId=amonystudio%40gmail.com&SubscriptionId=sc_e23fd949db296c6d4bcd3eefe21f8&Name=AYRAT+TONDUVAY&Email=amonystudio%40gmail.com&DateTime=2019-09-14+13%3a01%3a50&IpAddress=192.168.3.24&IpCountry=&IpCity=&IpRegion=&IpDistrict=&IpLatitude=&IpLongitude=&CardFirstSix=427631&CardLastFour=3783&CardType=Visa&CardExpDate=10%2f21&Issuer=SBERBANK+of+Russia&IssuerBankCountry=RU&Description=%d0%95%d0%b6%d0%b5%d0%bc%d0%b5%d1%81%d1%8f%d1%87%d0%bd%d0%b0%d1%8f+%d0%bf%d0%be%d0%b4%d0%bf%d0%b8%d1%81%d0%ba%d0%b0+%d0%bd%d0%b0+%d1%82%d0%b0%d1%80%d0%b8%d1%84+Business+%d0%ba+%d0%b1%d0%be%d1%82%d1%83+Amony+fit(id%3d129)%2c+inbot24.ru&AuthCode=223446&Token=545860796&TestMode=0&Status=Completed&GatewayName=Tinkoff&TotalFee=0.04&CardProduct=F'
ERROR:root:b'TransactionId=204123571&Amount=1.00&Currency=RUB&PaymentAmount=1.00&PaymentCurrency=RUB&OperationType=Payment&InvoiceId=&AccountId=amonystudio%40gmail.com&SubscriptionId=sc_17a524757e366c1883d1d84cb027a&Name=AYRAT+TONDUVAY&Email=amonystudio%40gmail.com&DateTime=2019-09-14+13%3a03%3a50&IpAddress=192.168.3.24&IpCountry=&IpCity=&IpRegion=&IpDistrict=&IpLatitude=&IpLongitude=&CardFirstSix=427631&CardLastFour=3783&CardType=Visa&CardExpDate=10%2f21&Issuer=SBERBANK+of+Russia&IssuerBankCountry=RU&Description=%d0%95%d0%b6%d0%b5%d0%bc%d0%b5%d1%81%d1%8f%d1%87%d0%bd%d0%b0%d1%8f+%d0%bf%d0%be%d0%b4%d0%bf%d0%b8%d1%81%d0%ba%d0%b0+%d0%bd%d0%b0+%d1%82%d0%b0%d1%80%d0%b8%d1%84+Business+%d0%ba+%d0%b1%d0%be%d1%82%d1%83+Amony+beauty(id%3d131)%2c+inbot24.ru&AuthCode=266017&Token=545861268&TestMode=0&Status=Completed&GatewayName=Tinkoff&TotalFee=0.04&CardProduct=F'
ERROR:django.request:Internal Server Error: /admin/cabinet/payment/5/change/
Traceback (most recent call last):
  File "/usr/local/lib/python3.7/site-packages/django/core/handlers/exception.py", line 34, in inner
    response = get_response(request)
  File "/usr/local/lib/python3.7/site-packages/django/core/handlers/base.py", line 145, in _get_response
    response = self.process_exception_by_middleware(e, request)
  File "/usr/local/lib/python3.7/site-packages/django/core/handlers/base.py", line 143, in _get_response
    response = response.render()
  File "/usr/local/lib/python3.7/site-packages/django/template/response.py", line 106, in render
    self.content = self.rendered_content
  File "/usr/local/lib/python3.7/site-packages/django/template/response.py", line 83, in rendered_content
    content = template.render(context, self._request)
  File "/usr/local/lib/python3.7/site-packages/django/template/backends/django.py", line 61, in render
    return self.template.render(context)
  File "/usr/local/lib/python3.7/site-packages/django/template/base.py", line 171, in render
    return self._render(context)
  File "/usr/local/lib/python3.7/site-packages/django/template/base.py", line 163, in _render
    return self.nodelist.render(context)
  File "/usr/local/lib/python3.7/site-packages/django/template/base.py", line 937, in render
    bit = node.render_annotated(context)
  File "/usr/local/lib/python3.7/site-packages/django/template/base.py", line 904, in render_annotated
    return self.render(context)
  File "/usr/local/lib/python3.7/site-packages/django/template/loader_tags.py", line 150, in render
    return compiled_parent._render(context)
  File "/usr/local/lib/python3.7/site-packages/django/template/base.py", line 163, in _render
    return self.nodelist.render(context)
  File "/usr/local/lib/python3.7/site-packages/django/template/base.py", line 937, in render
    bit = node.render_annotated(context)
  File "/usr/local/lib/python3.7/site-packages/django/template/base.py", line 904, in render_annotated
    return self.render(context)
  File "/usr/local/lib/python3.7/site-packages/django/template/loader_tags.py", line 150, in render
    return compiled_parent._render(context)
  File "/usr/local/lib/python3.7/site-packages/django/template/base.py", line 163, in _render
    return self.nodelist.render(context)
  File "/usr/local/lib/python3.7/site-packages/django/template/base.py", line 937, in render
    bit = node.render_annotated(context)
  File "/usr/local/lib/python3.7/site-packages/django/template/base.py", line 904, in render_annotated
    return self.render(context)
  File "/usr/local/lib/python3.7/site-packages/django/template/defaulttags.py", line 309, in render
    return nodelist.render(context)
  File "/usr/local/lib/python3.7/site-packages/django/template/base.py", line 937, in render
    bit = node.render_annotated(context)
  File "/usr/local/lib/python3.7/site-packages/django/template/base.py", line 904, in render_annotated
    return self.render(context)
  File "/usr/local/lib/python3.7/site-packages/django/template/loader_tags.py", line 62, in render
    result = block.nodelist.render(context)
  File "/usr/local/lib/python3.7/site-packages/django/template/base.py", line 937, in render
    bit = node.render_annotated(context)
  File "/usr/local/lib/python3.7/site-packages/django/template/base.py", line 904, in render_annotated
    return self.render(context)
  File "/usr/local/lib/python3.7/site-packages/django/template/defaulttags.py", line 309, in render
    return nodelist.render(context)
  File "/usr/local/lib/python3.7/site-packages/django/template/base.py", line 937, in render
    bit = node.render_annotated(context)
  File "/usr/local/lib/python3.7/site-packages/django/template/base.py", line 904, in render_annotated
    return self.render(context)
  File "/usr/local/lib/python3.7/site-packages/django/template/base.py", line 987, in render
    output = self.filter_expression.resolve(context)
  File "/usr/local/lib/python3.7/site-packages/django/template/base.py", line 698, in resolve
    new_obj = func(obj, *arg_vals)
  File "/usr/local/lib/python3.7/site-packages/django/template/defaultfilters.py", line 42, in _dec
    args[0] = str(args[0])
TypeError: __str__ returned non-string (type int)
ERROR:django.request:Internal Server Error: /admin/cabinet/payment/7/change/
Traceback (most recent call last):
  File "/usr/local/lib/python3.7/site-packages/django/core/handlers/exception.py", line 34, in inner
    response = get_response(request)
  File "/usr/local/lib/python3.7/site-packages/django/core/handlers/base.py", line 145, in _get_response
    response = self.process_exception_by_middleware(e, request)
  File "/usr/local/lib/python3.7/site-packages/django/core/handlers/base.py", line 143, in _get_response
    response = response.render()
  File "/usr/local/lib/python3.7/site-packages/django/template/response.py", line 106, in render
    self.content = self.rendered_content
  File "/usr/local/lib/python3.7/site-packages/django/template/response.py", line 83, in rendered_content
    content = template.render(context, self._request)
  File "/usr/local/lib/python3.7/site-packages/django/template/backends/django.py", line 61, in render
    return self.template.render(context)
  File "/usr/local/lib/python3.7/site-packages/django/template/base.py", line 171, in render
    return self._render(context)
  File "/usr/local/lib/python3.7/site-packages/django/template/base.py", line 163, in _render
    return self.nodelist.render(context)
  File "/usr/local/lib/python3.7/site-packages/django/template/base.py", line 937, in render
    bit = node.render_annotated(context)
  File "/usr/local/lib/python3.7/site-packages/django/template/base.py", line 904, in render_annotated
    return self.render(context)
  File "/usr/local/lib/python3.7/site-packages/django/template/loader_tags.py", line 150, in render
    return compiled_parent._render(context)
  File "/usr/local/lib/python3.7/site-packages/django/template/base.py", line 163, in _render
    return self.nodelist.render(context)
  File "/usr/local/lib/python3.7/site-packages/django/template/base.py", line 937, in render
    bit = node.render_annotated(context)
  File "/usr/local/lib/python3.7/site-packages/django/template/base.py", line 904, in render_annotated
    return self.render(context)
  File "/usr/local/lib/python3.7/site-packages/django/template/loader_tags.py", line 150, in render
    return compiled_parent._render(context)
  File "/usr/local/lib/python3.7/site-packages/django/template/base.py", line 163, in _render
    return self.nodelist.render(context)
  File "/usr/local/lib/python3.7/site-packages/django/template/base.py", line 937, in render
    bit = node.render_annotated(context)
  File "/usr/local/lib/python3.7/site-packages/django/template/base.py", line 904, in render_annotated
    return self.render(context)
  File "/usr/local/lib/python3.7/site-packages/django/template/defaulttags.py", line 309, in render
    return nodelist.render(context)
  File "/usr/local/lib/python3.7/site-packages/django/template/base.py", line 937, in render
    bit = node.render_annotated(context)
  File "/usr/local/lib/python3.7/site-packages/django/template/base.py", line 904, in render_annotated
    return self.render(context)
  File "/usr/local/lib/python3.7/site-packages/django/template/loader_tags.py", line 62, in render
    result = block.nodelist.render(context)
  File "/usr/local/lib/python3.7/site-packages/django/template/base.py", line 937, in render
    bit = node.render_annotated(context)
  File "/usr/local/lib/python3.7/site-packages/django/template/base.py", line 904, in render_annotated
    return self.render(context)
  File "/usr/local/lib/python3.7/site-packages/django/template/defaulttags.py", line 309, in render
    return nodelist.render(context)
  File "/usr/local/lib/python3.7/site-packages/django/template/base.py", line 937, in render
    bit = node.render_annotated(context)
  File "/usr/local/lib/python3.7/site-packages/django/template/base.py", line 904, in render_annotated
    return self.render(context)
  File "/usr/local/lib/python3.7/site-packages/django/template/base.py", line 987, in render
    output = self.filter_expression.resolve(context)
  File "/usr/local/lib/python3.7/site-packages/django/template/base.py", line 698, in resolve
    new_obj = func(obj, *arg_vals)
  File "/usr/local/lib/python3.7/site-packages/django/template/defaultfilters.py", line 42, in _dec
    args[0] = str(args[0])
TypeError: __str__ returned non-string (type int)
ERROR:root:b'TransactionId=205607575&Amount=1199.00&Currency=RUB&PaymentAmount=1199.00&PaymentCurrency=RUB&OperationType=Payment&InvoiceId=&AccountId=mergen%40irgit.net&SubscriptionId=sc_06ba33ac1c419ed0251e5913705d9&Name=MERGEN+IRGIT&Email=mergen%40irgit.net&DateTime=2019-09-17+10%3a31%3a00&IpAddress=192.168.3.34&IpCountry=&IpCity=&IpRegion=&IpDistrict=&IpLatitude=&IpLongitude=&CardFirstSix=555947&CardLastFour=8477&CardType=MasterCard&CardExpDate=01%2f21&Issuer=JOINT+STOCK+COMPANY+%22ALFA-BANK%22&IssuerBankCountry=RU&Description=%d0%95%d0%b6%d0%b5%d0%bc%d0%b5%d1%81%d1%8f%d1%87%d0%bd%d0%b0%d1%8f+%d0%bf%d0%be%d0%b4%d0%bf%d0%b8%d1%81%d0%ba%d0%b0+%d0%bd%d0%b0+%d1%82%d0%b0%d1%80%d0%b8%d1%84+Business+%d0%ba+%d0%b1%d0%be%d1%82%d1%83+%d0%a2%d1%8b%d0%b2%d0%b0+%d0%bc%d0%b0%d0%bd%d1%87%d1%8b(id%3d130)%2c+inbot24.ru&AuthCode=3M74Y2&Token=546879463&TestMode=0&Status=Completed&GatewayName=Tinkoff&TotalFee=46.76&CardProduct=MNW'
WARNING:django.request:Forbidden: /api/analytics_data/119/
WARNING:django.request:Forbidden: /api/botusers/119/
WARNING:django.request:Forbidden: /api/compaign_list/119/
WARNING:django.request:Forbidden: /api/botusers/119/
WARNING:django.request:Forbidden: /api/analytics_data/119/
WARNING:django.request:Forbidden: /api/analytics_data/119/
ERROR:root:b'TransactionId=206220473&Amount=1199.00&Currency=RUB&PaymentAmount=1199.00&PaymentCurrency=RUB&OperationType=Payment&InvoiceId=&AccountId=natka.90.1990%40gmail.com&SubscriptionId=sc_351af8d5dc4196993d4763e3af193&Name=NATALYA+VASILENKO&Email=natka.90.1990%40gmail.com&DateTime=2019-09-18+14%3a10%3a00&IpAddress=192.168.3.34&IpCountry=&IpCity=&IpRegion=&IpDistrict=&IpLatitude=&IpLongitude=&CardFirstSix=521324&CardLastFour=2576&CardType=MasterCard&CardExpDate=11%2f23&Issuer=TINKOFF+BANK&IssuerBankCountry=RU&Description=%d0%95%d0%b6%d0%b5%d0%bc%d0%b5%d1%81%d1%8f%d1%87%d0%bd%d0%b0%d1%8f+%d0%bf%d0%be%d0%b4%d0%bf%d0%b8%d1%81%d0%ba%d0%b0+%d0%bd%d0%b0+%d1%82%d0%b0%d1%80%d0%b8%d1%84+Business+%d0%ba+%d0%b1%d0%be%d1%82%d1%83+%d0%9d%d0%b0%d1%80%d0%b0%d1%89%d0%b8%d0%b2%d0%b0%d0%bd%d0%b8%d0%b5+%d1%80%d0%b5%d1%81%d0%bd%d0%b8%d1%86(id%3d139)%2c+inbot24.ru&AuthCode=022511&Token=547279521&TestMode=0&Status=Completed&GatewayName=Tinkoff&TotalFee=46.76&CardProduct=MNW'
WARNING:django.request:Not Found: /administrator/index.php
WARNING:django.request:Not Found: /admin/index.php
WARNING:django.request:Not Found: /admin.php
WARNING:django.request:Forbidden: /api/compaign_list/132/
WARNING:django.request:Unauthorized: /api/token/
WARNING:django.request:Forbidden: /api/analytics_data/145/
WARNING:django.request:Forbidden: /api/botusers/145/
WARNING:django.request:Forbidden: /api/compaign_list/145/
ERROR:root:b'TransactionId=212140029&Amount=1.00&Currency=RUB&PaymentAmount=1.00&PaymentCurrency=RUB&OperationType=Payment&InvoiceId=&AccountId=orlan_mh94%40mail.ru&SubscriptionId=sc_facb0e3d678bcf0b01ba8860069a6&Name=MOMENTUM+R&Email=orlan_mh94%40mail.ru&DateTime=2019-09-29+10%3a07%3a01&IpAddress=192.168.3.27&IpCountry=&IpCity=&IpRegion=&IpDistrict=&IpLatitude=&IpLongitude=&CardFirstSix=533669&CardLastFour=7481&CardType=MasterCard&CardExpDate=08%2f21&Issuer=SBERBANK+OF+RUSSIA&IssuerBankCountry=RU&Description=%d0%95%d0%b6%d0%b5%d0%bc%d0%b5%d1%81%d1%8f%d1%87%d0%bd%d0%b0%d1%8f+%d0%bf%d0%be%d0%b4%d0%bf%d0%b8%d1%81%d0%ba%d0%b0+%d0%bd%d0%b0+%d1%82%d0%b0%d1%80%d0%b8%d1%84+Business+%d0%ba+%d0%b1%d0%be%d1%82%d1%83+TEST(id%3d111)%2c+inbot24.ru&AuthCode=234142&Token=540254574&TestMode=0&Status=Completed&GatewayName=Tinkoff&TotalFee=0.04&CardProduct=MCS'
WARNING:django.request:Not Found: /adminer.php
WARNING:django.request:Forbidden: /api/compaign_list/112/
WARNING:django.request:Forbidden: /api/botusers/112/
WARNING:django.request:Forbidden: /api/analytics_data/112/
WARNING:django.request:Forbidden: /api/compaign_list/112/
WARNING:django.request:Forbidden: /api/compaign_list/112/
WARNING:django.request:Forbidden: /api/compaign_list/112/
WARNING:django.request:Forbidden: /api/analytics_data/112/
WARNING:django.request:Forbidden: /api/botusers/112/
WARNING:django.request:Forbidden: /api/compaign_list/112/
WARNING:django.request:Forbidden: /api/botusers/112/
WARNING:django.request:Forbidden: /api/analytics_data/112/
WARNING:django.request:Forbidden: /api/botusers/112/
WARNING:django.request:Forbidden: /api/analytics_data/112/
WARNING:django.request:Forbidden: /api/botusers/112/
WARNING:django.request:Forbidden: /api/compaign_list/112/
WARNING:django.request:Forbidden: /api/analytics_data/112/
WARNING:django.request:Forbidden: /api/botusers/112/
WARNING:django.request:Forbidden: /api/compaign_list/112/
WARNING:django.request:Forbidden: /api/botusers/112/
WARNING:django.request:Forbidden: /api/analytics_data/112/
WARNING:django.request:Forbidden: /api/analytics_data/112/
WARNING:django.request:Forbidden: /api/botusers/112/
WARNING:django.request:Forbidden: /api/compaign_list/112/
WARNING:django.request:Forbidden: /api/compaign_list/112/
WARNING:django.request:Forbidden: /api/botusers/112/
WARNING:django.request:Forbidden: /api/analytics_data/112/
WARNING:django.request:Unauthorized: /api/bot_list/
WARNING:django.request:Forbidden: /api/botusers/112/
WARNING:django.request:Forbidden: /api/analytics_data/112/
WARNING:django.request:Forbidden: /api/botusers/112/
WARNING:django.request:Forbidden: /api/compaign_list/112/
WARNING:django.request:Unauthorized: /api/bot_list/
ERROR:root:b'TransactionId=216133717&Amount=1.00&Currency=RUB&PaymentAmount=1.00&PaymentCurrency=RUB&OperationType=Payment&InvoiceId=&AccountId=nurarip%40yandex.ru&SubscriptionId=sc_1422987a13cc6d89c5ac709ea974a&Name=ARIP+NURMAGOMEDOV&Email=nurarip%40yandex.ru&DateTime=2019-10-06+10%3a59%3a01&IpAddress=192.168.3.27&IpCountry=&IpCity=&IpRegion=&IpDistrict=&IpLatitude=&IpLongitude=&CardFirstSix=521324&CardLastFour=0913&CardType=MasterCard&CardExpDate=04%2f21&Issuer=TINKOFF+BANK&IssuerBankCountry=RU&Description=%d0%95%d0%b6%d0%b5%d0%bc%d0%b5%d1%81%d1%8f%d1%87%d0%bd%d0%b0%d1%8f+%d0%bf%d0%be%d0%b4%d0%bf%d0%b8%d1%81%d0%ba%d0%b0+%d0%bd%d0%b0+%d1%82%d0%b0%d1%80%d0%b8%d1%84+Business+%d0%ba+%d0%b1%d0%be%d1%82%d1%83+Test(id%3d116)%2c+inbot24.ru&AuthCode=062890&Token=543011578&TestMode=0&Status=Completed&GatewayName=Tinkoff&TotalFee=0.04&CardProduct=MNW'
WARNING:django.request:Forbidden: /api/analytics_data/146/
WARNING:django.request:Forbidden: /api/botusers/146/
WARNING:django.request:Forbidden: /api/compaign_list/146/
WARNING:django.request:Forbidden: /api/analytics_data/146/
WARNING:django.request:Forbidden: /api/botusers/146/
WARNING:django.request:Forbidden: /api/analytics_data/146/
WARNING:django.request:Forbidden: /api/botusers/146/
WARNING:django.request:Forbidden: /api/compaign_list/146/
WARNING:django.request:Forbidden: /api/analytics_data/146/
WARNING:django.request:Forbidden: /api/analytics_data/146/
WARNING:django.request:Forbidden: /api/botusers/146/
WARNING:django.request:Forbidden: /api/compaign_list/146/
WARNING:django.request:Forbidden: /api/analytics_data/146/
WARNING:django.request:Forbidden: /api/botusers/146/
WARNING:django.request:Forbidden: /api/analytics_data/146/
WARNING:django.request:Forbidden: /api/botusers/146/
WARNING:django.request:Forbidden: /api/compaign_list/146/
WARNING:django.request:Forbidden: /api/botusers/146/
WARNING:django.request:Forbidden: /api/analytics_data/146/
WARNING:django.request:Forbidden: /api/compaign_list/147/
WARNING:django.request:Unauthorized: /api/token/
WARNING:django.request:Unauthorized: /api/token/
WARNING:django.request:Unauthorized: /api/token/
WARNING:django.request:Unauthorized: /api/token/
WARNING:django.request:Unauthorized: /api/token/
WARNING:django.request:Unauthorized: /api/token/
WARNING:django.request:Unauthorized: /api/token/
WARNING:django.request:Unauthorized: /api/token/
WARNING:django.request:Not Found: /admin/assets/js/views/login.js
WARNING:django.request:Not Found: /admin/i18n/readme.txt
WARNING:django.request:Not Found: /admin/config.php
WARNING:django.request:Forbidden: /api/analytics_data/119/
WARNING:django.request:Forbidden: /api/botusers/119/
WARNING:django.request:Forbidden: /api/compaign_list/119/
WARNING:django.request:Not Found: /admin/config.php
WARNING:django.request:Not Found: /admin/config.php
WARNING:django.request:Unauthorized: /api/token/
WARNING:django.request:Unauthorized: /api/token/
WARNING:django.request:Unauthorized: /api/token/
WARNING:django.request:Unauthorized: /api/token/
WARNING:django.request:Unauthorized: /api/token/
WARNING:django.request:Unauthorized: /api/token/
WARNING:django.request:Unauthorized: /api/token/
WARNING:django.request:Unauthorized: /api/token/
WARNING:django.request:Bad Request: /api/register/
WARNING:django.request:Bad Request: /api/register/
WARNING:django.request:Bad Request: /api/register/
WARNING:django.request:Bad Request: /api/register/
WARNING:django.request:Bad Request: /api/register/
WARNING:django.request:Bad Request: /api/register/
WARNING:django.request:Bad Request: /api/register/
WARNING:django.request:Bad Request: /api/register/
WARNING:django.request:Bad Request: /api/register/
WARNING:django.request:Bad Request: /api/register/
WARNING:django.request:Bad Request: /api/register/
WARNING:django.request:Bad Request: /api/register/
WARNING:django.request:Bad Request: /api/register/
WARNING:django.request:Bad Request: /api/register/
WARNING:django.request:Bad Request: /api/register/
WARNING:django.request:Bad Request: /api/register/
WARNING:django.request:Unauthorized: /api/token/
WARNING:django.request:Bad Request: /api/register/
WARNING:django.request:Bad Request: /api/register/
WARNING:django.request:Bad Request: /api/register/
WARNING:django.request:Bad Request: /api/register/
